Workbook

Sheet ダッシュボード
A1: SFF大会 収益シミュレーション ダッシュボード
A3: 【目標設定】
A4: 売上目標（2大会合計） | C4: 51653879 | D4: ※前年比120%
A5: 限界利益率目標 | C5: 0.5
A7: 【KPIサマリー（2大会合計）】
A8: 項目 | B8: PJT1 | C8: PJT2 | D8: 合計 | E8: 目標 | F8: 達成率
A9: 売上合計 | B9: ='PJT1_収支'!B4 -> 33990000 | C9: ='PJT2_収支'!B4 -> 20542000 | D9: =B9+C9 -> 54532000 | E9: =C4 -> 51653879 | F9: =IF(E9=0,0,D9/E9) -> 1.0557194
A10: 変動費合計 | B10: ='PJT1_収支'!B5 -> 25403240 | C10: ='PJT2_収支'!B5 -> 25403240 | D10: =B10+C10 -> 50806480 | E10: - | F10: -
A11: 限界利益 | B11: ='PJT1_収支'!B6 -> 8586760 | C11: ='PJT2_収支'!B6 -> -4861240 | D11: =B11+C11 -> 3725520 | E11: =D9*C5 -> 27266000 | F11: =IF(E11=0,0,D11/E11) -> 0.1366361
A12: 限界利益率 | B12: ='PJT1_収支'!B7 -> 0.25262607 | C12: ='PJT2_収支'!B7 -> -0.23664882 | D12: =IF(D9=0,0,D11/D9) -> 0.068318052 | E12: =C5 -> 0.5 | F12: =IF(E12=0,0,D12/E12) -> 0.1366361
A14: 【達成判定】
A15: 売上目標 | B15: =IF(D9>=C4,"✓ 達成","✗ 未達") -> ✓ 達成
A16: 利益率目標 | B16: =IF(D12>=C5,"✓ 達成","✗ 未達") -> ✗ 未達
A18: 【大会別 収益内訳】
A19: 収益項目 | B19: PJT1 | C19: PJT2 | D19: 合計
A20: 選手売上 | B20: ='PJT1_収支'!B11 -> 6122000 | C20: ='PJT2_収支'!B11 -> 6122000 | D20: =B20+C20 -> 12244000
A21: 観客売上 | B21: ='PJT1_収支'!B12 -> 18468000 | C21: ='PJT2_収支'!B12 -> 12120000 | D21: =B21+C21 -> 30588000
A22: スポンサー売上 | B22: ='PJT1_収支'!B13 -> 8400000 | C22: ='PJT2_収支'!B13 -> 1300000 | D22: =B22+C22 -> 9700000
A23: 付帯収入 | B23: ='PJT1_収支'!B14 -> 1000000 | C23: ='PJT2_収支'!B14 -> 1000000 | D23: =B23+C23 -> 2000000

Sheet PJT1_入力
A1: PJT1（パープルホール）入力シート
A3: 【選手】
A4: カテゴリ | B4: 単価 | C4: 人数 | D4: 売上
A5: WantToBe | B5: 30000 | C5: 20 | D5: =B5*C5 -> 600000
A6: 一般 | B6: 20000 | C6: 220 | D6: =B6*C6 -> 4400000
A7: Wエントリー | B7: 8000 | C7: 0 | D7: =B7*C7 -> 0
A8: 学生/新人 | B8: 8000 | C8: 0 | D8: =B8*C8 -> 0
A9: バックサポート | B9: 3300 | C9: =C6*1.5 -> 330 | D9: =B9*C9 -> 1089000
A10: ステージパートナー | B10: 3300 | C10: 10 | D10: =B10*C10 -> 33000
A11: 選手売上 小計 | D11: =SUM(D5:D10) -> 6122000
A13: 【観客】 | J13: =11*12*3.5 -> 462
A14: 席種 | B14: 単価 | C14: キャパ | D14: 販売数 | E14: 売上 | F14: 充足率
A15: VIP席 | B15: 50000 | C15: =G15*2 -> 60 | D15: =C15*F15 -> 18 | E15: =B15*D15 -> 900000 | F15: 0.3 | G15: 30
A16: S席 | B16: 10000 | C16: =G16*2 -> 1200 | D16: =C16*F16 -> 1200 | E16: =B16*D16 -> 12000000 | F16: 1 | G16: 600
A17: A席 | B17: 9000 | C17: =G17*2 -> 920 | D17: =C17*F17 -> 552 | E17: =B17*D17 -> 4968000 | F17: 0.6 | G17: 460
A18: B席 | B18: 5000 | C18: =G18*2 -> 200 | D18: =C18*F18 -> 120 | E18: =B18*D18 -> 600000 | F18: 0.6 | G18: 100
A19: 観客売上 小計 | C19: =SUM(C15:C18) -> 2380 | D19: =SUM(D15:D18) -> 1890 | E19: =SUM(E15:E18) -> 18468000 | F19: =IF(C19=0,0,D19/C19) -> 0.79411765 | G19: =C19/2 -> 1190
A21: 【スポンサー】
A22: プラン | B22: 単価 | C22: 社数 | D22: 売上 | F22: 現状社数
A23: TOPパートナー | B23: 5000000 | C23: 1 | D23: =B23*C23 -> 5000000 | F23: 1
A24: DIAMOND | B24: 700000 | C24: 4 | D24: =B24*C24 -> 2800000 | F24: 4
A25: PLATINUM | B25: 300000 | C25: 2 | D25: =B25*C25 -> 600000 | F25: 4
D26: =B26*C26 -> 0 | F26: 0
A27: スポンサー売上 小計 | D27: =SUM(D23:D26) -> 8400000
A29: 【付帯収入】
A30: 項目 | B30: 売上
A31: 物販売上 | B31: 800000 | D31: 単価
A32: フォトレコ | B32: 0 | C32: 80人くらいの購入→ | D32: 2000
A33: 動画販売 | B33: 0 | D33: 3000
A34: カラーリング | B34: 200000
A35: 付帯収入 小計 | B35: =SUM(B31:B34) -> 1000000

Sheet PJT2_入力
A1: PJT2（ひらしん）入力シート
A3: 【選手】
A4: カテゴリ | B4: 単価 | C4: 人数 | D4: 売上
A5: WantToBe | B5: 30000 | C5: 20 | D5: =B5*C5 -> 600000
A6: 一般 | B6: 20000 | C6: 220 | D6: =B6*C6 -> 4400000
A7: Wエントリー | B7: 8000 | C7: 0 | D7: =B7*C7 -> 0
A8: 学生/新人 | B8: 8000 | C8: 0 | D8: =B8*C8 -> 0
A9: バックサポート | B9: 3300 | C9: =C6*1.5 -> 330 | D9: =B9*C9 -> 1089000
A10: ステージパートナー | B10: 3300 | C10: 10 | D10: =B10*C10 -> 33000
A11: 選手売上 小計 | D11: =SUM(D5:D10) -> 6122000
A13: 【観客】
A14: 席種 | B14: 単価 | C14: キャパ | D14: 販売数 | E14: 売上 | F14: 充足率
A15: VIP席 | B15: 50000 | C15: 20 | D15: =C15*F15 -> 6 | E15: =B15*D15 -> 300000 | F15: 0.3
A16: S席 | B16: 10000 | C16: 300 | D16: =C16*F16 -> 300 | E16: =B16*D16 -> 3000000 | F16: 1
A17: A席 | B17: 9000 | C17: 1300 | D17: =C17*F17 -> 780 | E17: =B17*D17 -> 7020000 | F17: 0.6
A18: B席 | B18: 5000 | C18: 600 | D18: =C18*F18 -> 360 | E18: =B18*D18 -> 1800000 | F18: 0.6
A19: 観客売上 小計 | C19: =SUM(C15:C18) -> 2220 | D19: =SUM(D15:D18) -> 1446 | E19: =SUM(E15:E18) -> 12120000 | F19: =IF(C19=0,0,D19/C19) -> 0.65135135
A21: 【スポンサー】
A22: プラン | B22: 単価 | C22: 社数 | D22: 売上 | F22: 現状社数
A23: TOPパートナー | B23: 5000000 | C23: 0 | D23: =B23*C23 -> 0 | F23: 1
A24: DIAMOND | B24: 700000 | C24: 1 | D24: =B24*C24 -> 700000 | F24: 4
A25: PLATINUM | B25: 300000 | C25: 2 | D25: =B25*C25 -> 600000 | F25: 4
D26: =B26*C26 -> 0 | F26: 0
A27: スポンサー売上 小計 | D27: =SUM(D23:D26) -> 1300000
A29: 【付帯収入】
A30: 項目 | B30: 売上
A31: 物販売上 | B31: 800000
A32: フォトレコ | B32: 0
A33: 動画販売 | B33: 0
A34: カラーリング | B34: 200000
A35: 付帯収入 小計 | B35: =SUM(B31:B34) -> 1000000

Sheet old_コスト
A1: 【コスト詳細】（関西：藤井寺パープルホール, 関東：ひらしん平塚文化芸術ホール）
A3: 費目 | B3: PJT1予算(円) | C3: PJT2予算(円) | D3: 備考 | E3: 2025実績参考
A4: 1. 会場関連費
A5: 会場使用料 | B5: 2500000 | C5: 2500000 | D5: 2日間
A6: 控室使用料 | B6: 100000 | C6: 100000 | D6: 審査員・選手控室
A7: カラーリング用別室 | B7: 50000 | C7: 50000 | D7: 追加レンタル
A8: 駐車場代 | B8: 30000 | C8: 30000 | D8: スタッフ・業者用
A9: 会場設営・撤去費 | B9: 500000 | C9: 500000 | D9: ステージ設営含む
A10: 2. 音響・照明・演出
A11: 音響機材・オペレーター | B11: 800000 | C11: 800000 | D11: 舞台監督経由
A12: 照明機材・オペレーター | B12: 700000 | C12: 700000 | D12: 舞台監督経由
A13: ステージデザイン制作 | B13: 500000 | C13: 500000 | D13: デザイン＋施工
A14: 舞台監督費 | B14: 500000 | C14: 500000 | D14: 請求書ベース
A15: 3. 人件費・業務委託費（当日）
A16: サポートスタッフ | B16: 135000 | C16: 135000 | D16: @9,000円×15名 | E16: 90,000〜150,000
A17: 審査員（トレーナー） | B17: 75000 | C17: 75000 | D17: @15,000円×5名 | E17: 45,000〜75,000
A18: 審査員（入賞者） | B18: 30000 | C18: 30000 | D18: @10,000円×3名 | E18: 17,958〜29,919
A19: 司会・MC | B19: 80000 | C19: 80000 | D19: 1〜2名 | E19: 30,000〜100,495
A20: 実況者 | B20: 30000 | C20: 30000 | D20: 桐原さん検討中
A21: カメラマン・編集 | B21: 70000 | C21: 70000 | D21: 1〜2名 | E21: 30,000〜90,000
A22: 4. 制作物費
A23: 物語ノート | B23: 200000 | C23: 0 | D23: 全選手分・PJT1で一括
A24: メッセージカード | B24: 15000 | C24: 0 | D24: 全選手分・PJT1で一括（A案：A6片面フルカラー、¥8,000〜15,000）
A25: 選手バッジ | B25: 50000 | C25: 0 | D25: 全選手分・PJT1で一括
A26: メダル（金・銀・銅） | B26: 150000 | C26: 150000 | D26: 各大会分
A27: パンフレット | B27: 150000 | C27: 150000 | D27: デザイン＋印刷
A28: ブースマップ | B28: 30000 | C28: 30000 | D28: 来場者配布用
A29: スタンプラリー用紙 | B29: 30000 | C29: 30000
A30: 台本・マニュアル印刷 | B30: 20000 | C30: 20000 | D30: スタッフ用
A31: 選手配布書類 | B31: 30000 | C31: 30000 | D31: 印刷＋カット作業
A32: 応援メッセージ | B32: 5000 | C32: 5000 | D32: ジム印刷
A33: 5. 動画・クリエイティブ制作
A34: オープニング動画 | B34: 100000 | C34: 0 | D34: PJT1で一括制作
A35: 企業ストーリー動画 | B35: 50000 | C35: 50000 | D35: 各大会分
A36: 事前MTG動画 | B36: 50000 | C36: 0 | D36: PJT1で一括
A37: SNSクリエイティブ | B37: 30000 | C37: 0 | D37: PJT1で一括
A38: 6. システム・Web関連
A39: 新HP開発・保守費 | B39: 300000 | C39: 0 | D39: フレアネスト・年間
A40: SFFマイページ開発費 | B40: 200000 | C40: 0 | D40: フレアネスト
A41: 決済手数料（3.6%） | B41: =('PJT1_入力'!D11+'PJT1_入力'!E19+'PJT1_入力'!D27+'PJT1_入力'!B35)*0.036 -> 1223640 | C41: =('PJT2_入力'!D11+'PJT2_入力'!E19+'PJT2_入力'!D27+'PJT2_入力'!B35)*0.036 -> 739512 | D41: 売上連動
...

Sheet コスト
A1: 【コスト詳細】（関西：藤井寺パープルホール, 関東：ひらしん平塚文化芸術ホール）
A3: 費目 | B3: PJT1予算(円) | C3: PJT2予算(円) | D3: 備考 | E3: 2025実績参考
A4: 1. 会場関連費
A5: 会場使用料 | B5: 2500000 | C5: 2500000 | D5: 2日間
A6: 控室使用料 | B6: 100000 | C6: 100000 | D6: 審査員・選手控室
A7: カラーリング用別室 | B7: 50000 | C7: 50000 | D7: 追加レンタル
A8: 駐車場代 | B8: 30000 | C8: 30000 | D8: スタッフ・業者用
A9: 会場設営・撤去費 | B9: 500000 | C9: 500000 | D9: ステージ設営含む
A10: 2. 音響・照明・演出
A11: 音響機材・オペレーター | B11: 800000 | C11: 800000 | D11: 舞台監督経由
A12: 照明機材・オペレーター | B12: 700000 | C12: 700000 | D12: 舞台監督経由
A13: ステージデザイン制作 | B13: 500000 | C13: 500000 | D13: デザイン＋施工
A14: 舞台監督費 | B14: 500000 | C14: 500000 | D14: 請求書ベース
A15: LEDビジョン費（要確認） | B15: 6622000 | C15: 0 | D15: ※giftworks見積Q-0000000044（税別）・舞台監督と内容整理中
A16: 3. 人件費・業務委託費（当日）
A17: サポートスタッフ | B17: 135000 | C17: 135000 | D17: @9,000円×15名 | E17: 90,000〜150,000
A18: 審査員（トレーナー） | B18: 75000 | C18: 75000 | D18: @15,000円×5名 | E18: 45,000〜75,000
A19: 審査員（入賞者） | B19: 30000 | C19: 30000 | D19: @10,000円×3名 | E19: 17,958〜29,919
A20: 司会・MC | B20: 80000 | C20: 80000 | D20: 1〜2名 | E20: 30,000〜100,495
A21: 実況者 | B21: 30000 | C21: 30000 | D21: 桐原さん検討中
A22: カメラマン・編集 | B22: 70000 | C22: 70000 | D22: 1〜2名
A23: 4. 制作物費
A24: 物語ノート | B24: 200000 | C24: 0 | D24: 全選手分・PJT1で一括
A25: メッセージカード | B25: 15000 | C25: 0 | D25: 全選手分・PJT1で一括（A案：A6片面フルカラー、¥8,000〜15,000）
A26: 選手バッジ | B26: 50000 | C26: 0 | D26: 全選手分・PJT1で一括
A27: メダル（金・銀・銅） | B27: 150000 | C27: 150000 | D27: 各大会分
A28: パンフレット | B28: 150000 | C28: 150000 | D28: デザイン＋印刷 | E28: ココナラデザイナー：¥81600
A29: ブースマップ | B29: 30000 | C29: 30000 | D29: 来場者配布用
A30: スタンプラリー用紙 | B30: 30000 | C30: 30000
A31: 台本・マニュアル印刷 | B31: 20000 | C31: 20000 | D31: スタッフ用
A32: 選手配布書類 | B32: 30000 | C32: 30000 | D32: 印刷＋カット作業
A33: 応援メッセージ | B33: 5000 | C33: 5000 | D33: ジム印刷
A34: フォトブース バックパネル | B34: 46000 | C34: 0 | D34: KILAMEK見積E-0490398（税別）・PJT1一括
A35: 5. 動画・クリエイティブ制作
A36: オープニング動画 | B36: 100000 | C36: 0 | D36: PJT1で一括制作
A37: 企業ストーリー動画 | B37: 50000 | C37: 50000 | D37: 各大会分
A38: 事前MTG動画 | B38: 50000 | C38: 0 | D38: PJT1で一括
A39: SNSクリエイティブ | B39: 30000 | C39: 0 | D39: PJT1で一括
A40: 6. システム・Web関連
A41: 新HP開発・保守費 | B41: 300000 | C41: 0 | D41: フレアネスト・年間
...

Sheet 実コスト
A1: 【コスト詳細】（関西：藤井寺パープルホール, 関東：ひらしん平塚文化芸術ホール）
A3: 費目 | B3: PJT1予算(円) | C3: PJT2予算(円) | D3: 備考 | E3: 2025実績参考
A4: 1. 会場関連費 | F4: →→→実コスト
A5: 会場使用料 | B5: 2500000 | C5: 2500000 | D5: 2日間
A6: 控室使用料 | B6: 100000 | C6: 100000 | D6: 審査員・選手控室
A7: カラーリング用別室 | B7: 50000 | C7: 50000 | D7: 追加レンタル
A8: 駐車場代 | B8: 30000 | C8: 30000 | D8: スタッフ・業者用
A9: 会場設営・撤去費 | B9: 500000 | C9: 500000 | D9: ステージ設営含む
A10: 2. 音響・照明・演出
A11: 音響機材・オペレーター | B11: 800000 | C11: 800000 | D11: 舞台監督経由
A12: 照明機材・オペレーター | B12: 700000 | C12: 700000 | D12: 舞台監督経由
A13: ステージデザイン制作 | B13: 500000 | C13: 500000 | D13: デザイン＋施工
A14: 舞台監督費 | B14: 500000 | C14: 500000 | D14: 請求書ベース
A15: 3. 人件費・業務委託費（当日）
A16: サポートスタッフ | B16: 135000 | C16: 135000 | D16: @9,000円×15名 | E16: 90,000〜150,000
A17: 審査員（トレーナー） | B17: 75000 | C17: 75000 | D17: @15,000円×5名 | E17: 45,000〜75,000
A18: 審査員（入賞者） | B18: 30000 | C18: 30000 | D18: @10,000円×3名 | E18: 17,958〜29,919
A19: 司会・MC | B19: 80000 | C19: 80000 | D19: 1〜2名 | E19: 30,000〜100,495
A20: 実況者 | B20: 30000 | C20: 30000 | D20: 桐原さん検討中
A21: カメラマン・編集 | B21: 70000 | C21: 70000 | D21: 1〜2名 | E21: 30,000〜90,000
A22: 4. 制作物費
A23: 物語ノート | B23: 200000 | C23: 0 | D23: 全選手分・PJT1で一括
A24: メッセージカード | B24: 15000 | C24: 0 | D24: 全選手分・PJT1で一括（A案：A6片面フルカラー、¥8,000〜15,000）
A25: 選手バッジ | B25: 50000 | C25: 0 | D25: 全選手分・PJT1で一括
A26: メダル（金・銀・銅） | B26: 150000 | C26: 150000 | D26: 各大会分
A27: パンフレット | B27: 150000 | C27: 150000 | D27: デザイン＋印刷
A28: ブースマップ | B28: 30000 | C28: 30000 | D28: 来場者配布用
A29: スタンプラリー用紙 | B29: 30000 | C29: 30000
A30: 台本・マニュアル印刷 | B30: 20000 | C30: 20000 | D30: スタッフ用
A31: 選手配布書類 | B31: 30000 | C31: 30000 | D31: 印刷＋カット作業
A32: 応援メッセージ | B32: 5000 | C32: 5000 | D32: ジム印刷
A33: 5. 動画・クリエイティブ制作
A34: オープニング動画 | B34: 100000 | C34: 0 | D34: PJT1で一括制作
A35: 企業ストーリー動画 | B35: 50000 | C35: 50000 | D35: 各大会分
A36: 事前MTG動画 | B36: 50000 | C36: 0 | D36: PJT1で一括
A37: SNSクリエイティブ | B37: 30000 | C37: 0 | D37: PJT1で一括
A38: 6. システム・Web関連
A39: 新HP開発・保守費 | B39: 300000 | C39: 0 | D39: フレアネスト・年間
A40: SFFマイページ開発費 | B40: 200000 | C40: 0 | D40: フレアネスト
A41: 決済手数料（3.6%） | B41: =('PJT1_入力'!D11+'PJT1_入力'!E19+'PJT1_入力'!D27+'PJT1_入力'!B35)*0.036 -> 1223640 | C41: =('PJT2_入力'!D11+'PJT2_入力'!E19+'PJT2_入力'!D27+'PJT2_入力'!B35)*0.036 -> 739512 | D41: 売上連動
...

Sheet PJT1_収支
A1: PJT1（パープルホール）収支計算
A3: 項目 | B3: 金額
A4: 売上合計 | B4: =B11+B12+B13+B14 -> 33990000
A5: 変動費合計 | B5: ='コスト'!B68 -> 25403240
A6: 限界利益 | B6: =B4-B5 -> 8586760
A7: 限界利益率 | B7: =IF(B4=0,0,B6/B4) -> 0.25262607
A9: 【売上内訳】
A10: カテゴリ | B10: 金額 | C10: 構成比
A11: 選手売上 | B11: ='PJT1_入力'!D11 -> 6122000 | C11: =IF($B$4=0,0,B11/$B$4) -> 0.1801118
A12: 観客売上 | B12: ='PJT1_入力'!E19 -> 18468000 | C12: =IF($B$4=0,0,B12/$B$4) -> 0.54333628
A13: スポンサー売上 | B13: ='PJT1_入力'!D27 -> 8400000 | C13: =IF($B$4=0,0,B13/$B$4) -> 0.24713151
A14: 付帯収入 | B14: ='PJT1_入力'!B35 -> 1000000 | C14: =IF($B$4=0,0,B14/$B$4) -> 0.029420418

Sheet PJT2_収支
A1: PJT2（ひらしん）収支計算
A3: 項目 | B3: 金額
A4: 売上合計 | B4: =B11+B12+B13+B14 -> 20542000
A5: 変動費合計 | B5: ='コスト'!B68 -> 25403240
A6: 限界利益 | B6: =B4-B5 -> -4861240
A7: 限界利益率 | B7: =IF(B4=0,0,B6/B4) -> -0.23664882
A9: 【売上内訳】
A10: カテゴリ | B10: 金額 | C10: 構成比
A11: 選手売上 | B11: ='PJT2_入力'!D11 -> 6122000 | C11: =IF($B$4=0,0,B11/$B$4) -> 0.29802356
A12: 観客売上 | B12: ='PJT2_入力'!E19 -> 12120000 | C12: =IF($B$4=0,0,B12/$B$4) -> 0.59001071
A13: スポンサー売上 | B13: ='PJT2_入力'!D27 -> 1300000 | C13: =IF($B$4=0,0,B13/$B$4) -> 0.063284977
A14: 付帯収入 | B14: ='PJT2_入力'!B35 -> 1000000 | C14: =IF($B$4=0,0,B14/$B$4) -> 0.048680752
