Workbook

Sheet 予算入力シート（全社売上）V2 ※入力不要
B1: ◆2026年2月期(計画) | D1: 計画 | E1: 計画 | F1: 計画 | G1: 計画 | H1: 計画 | I1: 計画 | J1: 計画 | K1: 計画 | L1: 計画 | M1: 計画 | N1: 計画 | O1: 計画
D2: =YEAR(D3)&MONTH(D3) -> 20263 | E2: =YEAR(E3)&MONTH(E3) -> 20264 | F2: =YEAR(F3)&MONTH(F3) -> 20265 | G2: =YEAR(G3)&MONTH(G3) -> 20266 | H2: =YEAR(H3)&MONTH(H3) -> 20267 | I2: =YEAR(I3)&MONTH(I3) -> 20268 | J2: =YEAR(J3)&MONTH(J3) -> 20269 | K2: =YEAR(K3)&MONTH(K3) -> 202610 | ... O2: =YEAR(O3)&MONTH(O3) -> 20272
B3: 事業/科目 | D3: 46112 | E3: =EOMONTH(D3,1) -> 46142 | F3: =EOMONTH(E3,1) -> 46173 | G3: =EOMONTH(F3,1) -> 46203 | H3: =EOMONTH(G3,1) -> 46234 | I3: =EOMONTH(H3,1) -> 46265 | J3: =EOMONTH(I3,1) -> 46295 | K3: =EOMONTH(J3,1) -> 46326 | L3: =EOMONTH(K3,1) -> 46356 | ... O3: =EOMONTH(N3,1) -> 46446 | P3: 合計 | Q3: 備考欄
B4: Ⅰ.SFF | S4: 前年比較 | U4: 46054 | V4: =EOMONTH(U4,12) -> 46446 | W4: 前年比
B5: 1 | C5: 協賛売上 | D5: ='予算入力シート（SFF）'!D5 -> 0 | E5: ='予算入力シート（SFF）'!E5 -> 0 | F5: ='予算入力シート（SFF）'!F5 -> 0 | G5: ='予算入力シート（SFF）'!G5 -> 0 | H5: ='予算入力シート（SFF）'!H5 -> 0 | I5: ='予算入力シート（SFF）'!I5 -> 1300000 | J5: ='予算入力シート（SFF）'!J5 -> 8400000 | K5: ='予算入力シート（SFF）'!K5 -> 0 | ... O5: ='予算入力シート（SFF）'!O5 -> 0 | P5: =SUM(D5:O5) -> 9700000 | S5: 1 | T5: SFF | U5: 43571 | V5: =P14/1000 -> 48385 | W5: =V5/U5 -> 1.1104863
B6: =B5+1 -> 2 | C6: 来場者売上 | D6: ='予算入力シート（SFF）'!D6 -> 0 | E6: ='予算入力シート（SFF）'!E6 -> 0 | F6: ='予算入力シート（SFF）'!F6 -> 0 | G6: ='予算入力シート（SFF）'!G6 -> 0 | H6: ='予算入力シート（SFF）'!H6 -> 0 | I6: ='予算入力シート（SFF）'!I6 -> 11940000 | J6: ='予算入力シート（SFF）'!J6 -> 11940000 | K6: ='予算入力シート（SFF）'!K6 -> 0 | ... O6: ='予算入力シート（SFF）'!O6 -> 0 | P6: =SUM(D6:O6) -> 23880000 | S6: =S5+1 -> 2 | T6: YouTube事業売上 | U6: 35361 | V6: =P27/1000 -> 30190 | W6: =V6/U6 -> 0.85376545
B7: =B6+1 -> 3 | C7: 選手 | D7: ='予算入力シート（SFF）'!D7 -> 0 | E7: ='予算入力シート（SFF）'!E7 -> 0 | F7: ='予算入力シート（SFF）'!F7 -> 0 | G7: ='予算入力シート（SFF）'!G7 -> 0 | H7: ='予算入力シート（SFF）'!H7 -> 0 | I7: ='予算入力シート（SFF）'!I7 -> 5033000 | J7: ='予算入力シート（SFF）'!J7 -> 5033000 | K7: ='予算入力シート（SFF）'!K7 -> 0 | ... O7: ='予算入力シート（SFF）'!O7 -> 0 | P7: =SUM(D7:O7) -> 10066000 | S7: =S6+1 -> 3 | T7: フィットネス事業売上 | U7: 21118 | V7: =P28/1000 -> 7700 | W7: =V7/U7 -> 0.36461786
B8: =B7+1 -> 4 | C8: バックサポート | D8: ='予算入力シート（SFF）'!D8 -> 0 | E8: ='予算入力シート（SFF）'!E8 -> 0 | F8: ='予算入力シート（SFF）'!F8 -> 0 | G8: ='予算入力シート（SFF）'!G8 -> 0 | H8: ='予算入力シート（SFF）'!H8 -> 0 | I8: ='予算入力シート（SFF）'!I8 -> 1089000 | J8: ='予算入力シート（SFF）'!J8 -> 1089000 | K8: ='予算入力シート（SFF）'!K8 -> 0 | ... O8: ='予算入力シート（SFF）'!O8 -> 0 | P8: =SUM(D8:O8) -> 2178000 | S8: =S7+1 -> 4 | T8: フィットネス事業売上（FC収入） | U8: 6801 | V8: =P29/1000 -> 2500 | W8: =V8/U8 -> 0.367593
B9: =B8+1 -> 5 | C9: 物販売上 | D9: ='予算入力シート（SFF）'!D9 -> 0 | E9: ='予算入力シート（SFF）'!E9 -> 0 | F9: ='予算入力シート（SFF）'!F9 -> 0 | G9: ='予算入力シート（SFF）'!G9 -> 0 | H9: ='予算入力シート（SFF）'!H9 -> 0 | I9: ='予算入力シート（SFF）'!I9 -> 400000 | J9: ='予算入力シート（SFF）'!J9 -> 400000 | K9: ='予算入力シート（SFF）'!K9 -> 0 | ... O9: ='予算入力シート（SFF）'!O9 -> 0 | P9: =SUM(D9:O9) -> 800000 | S9: =S8+1 -> 5 | T9: アパレル売上 | U9: 2759 | V9: =P30/1000 -> 1500 | W9: =V9/U9 -> 0.54367524
B10: =B9+1 -> 6 | C10: フォトレコ | D10: ='予算入力シート（SFF）'!D10 -> 0 | E10: ='予算入力シート（SFF）'!E10 -> 0 | F10: ='予算入力シート（SFF）'!F10 -> 0 | G10: ='予算入力シート（SFF）'!G10 -> 0 | H10: ='予算入力シート（SFF）'!H10 -> 0 | I10: ='予算入力シート（SFF）'!I10 -> 600000 | J10: ='予算入力シート（SFF）'!J10 -> 600000 | K10: ='予算入力シート（SFF）'!K10 -> 0 | ... O10: ='予算入力シート（SFF）'!O10 -> 0 | P10: =SUM(D10:O10) -> 1200000 | T10: 売上高 | U10: =SUM(U5:U9) -> 109610 | V10: =SUM(V5:V9) -> 90275 | W10: =V10/U10 -> 0.82360186
B11: =B10+1 -> 7 | C11: 動画販売 | D11: ='予算入力シート（SFF）'!D11 -> 0 | E11: ='予算入力シート（SFF）'!E11 -> 0 | F11: ='予算入力シート（SFF）'!F11 -> 0 | G11: ='予算入力シート（SFF）'!G11 -> 0 | H11: ='予算入力シート（SFF）'!H11 -> 0 | I11: ='予算入力シート（SFF）'!I11 -> 198000 | J11: ='予算入力シート（SFF）'!J11 -> 198000 | K11: ='予算入力シート（SFF）'!K11 -> 0 | ... O11: ='予算入力シート（SFF）'!O11 -> 0 | P11: =SUM(D11:O11) -> 396000 | S11: =S9+1 -> 6 | T11: SFF | U11: 13657 | V11: =P23/1000 -> 31366.26 | W11: =V11/U11 -> 2.2967167
B12: =B11+1 -> 8 | C12: カラーリング | D12: ='予算入力シート（SFF）'!D12 -> 0 | E12: ='予算入力シート（SFF）'!E12 -> 0 | F12: ='予算入力シート（SFF）'!F12 -> 0 | G12: ='予算入力シート（SFF）'!G12 -> 0 | H12: ='予算入力シート（SFF）'!H12 -> 0 | I12: ='予算入力シート（SFF）'!I12 -> 82500 | J12: ='予算入力シート（SFF）'!J12 -> 82500 | K12: ='予算入力シート（SFF）'!K12 -> 0 | ... O12: ='予算入力シート（SFF）'!O12 -> 0 | P12: =SUM(D12:O12) -> 165000 | S12: =S11+1 -> 7 | T12: YouTube経費 | U12: 506 | V12: =O32 -> 0 | W12: =V12/U12 -> 0
B13: =B12+1 -> 9 | C13: SFFその他 | D13: ='予算入力シート（SFF）'!D13 -> 0 | E13: ='予算入力シート（SFF）'!E13 -> 0 | F13: ='予算入力シート（SFF）'!F13 -> 0 | G13: ='予算入力シート（SFF）'!G13 -> 0 | H13: ='予算入力シート（SFF）'!H13 -> 0 | I13: ='予算入力シート（SFF）'!I13 -> 0 | J13: ='予算入力シート（SFF）'!J13 -> 0 | K13: ='予算入力シート（SFF）'!K13 -> 0 | ... O13: ='予算入力シート（SFF）'!O13 -> 0 | P13: =SUM(D13:O13) -> 0 | S13: =S12+1 -> 8 | T13: アパレル仕入高 | U13: 528 | V13: =O34 -> 0 | W13: =V13/U13 -> 0
C14: 売上合計 | D14: =SUM(D5:D13) -> 0 | E14: =SUM(E5:E13) -> 0 | F14: =SUM(F5:F13) -> 0 | G14: =SUM(G5:G13) -> 0 | H14: =SUM(H5:H13) -> 0 | I14: =SUM(I5:I13) -> 20642500 | J14: =SUM(J5:J13) -> 27742500 | K14: =SUM(K5:K13) -> 0 | ... O14: =SUM(O5:O13) -> 0 | P14: =SUM(D14:O14) -> 48385000 | S14: =S13+1 -> 9 | T14: フィットネス業務委託費 | U14: 10452 | V14: =P35/1000 -> 4990 | W14: =V14/U14 -> 0.47742059
B15: =B13+1 -> 10 | C15: 支払手数料 | D15: ='予算入力シート（SFF）'!D15+'予算入力シート（SFF）'!D16+'予算入力シート（SFF）'!D17+'予算入力シート（SFF）'!D18+'予算入力シート（SFF）'!D19 -> 0 | E15: ='予算入力シート（SFF）'!E15+'予算入力シート（SFF）'!E16+'予算入力シート（SFF）'!E17+'予算入力シート（SFF）'!E18+'予算入力シート（SFF）'!E19 -> 0 | F15: ='予算入力シート（SFF）'!F15+'予算入力シート（SFF）'!F16+'予算入力シート（SFF）'!F17+'予算入力シート（SFF）'!F18+'予算入力シート（SFF）'!F19 -> 0 | G15: ='予算入力シート（SFF）'!G15+'予算入力シート（SFF）'!G16+'予算入力シート（SFF）'!G17+'予算入力シート（SFF）'!G18+'予算入力シート（SFF）'!G19 -> 0 | H15: ='予算入力シート（SFF）'!H15+'予算入力シート（SFF）'!H16+'予算入力シート（SFF）'!H17+'予算入力シート（SFF）'!H18+'予算入力シート（SFF）'!H19 -> 0 | I15: ='予算入力シート（SFF）'!I15+'予算入力シート（SFF）'!I16+'予算入力シート（SFF）'!I17+'予算入力シート（SFF）'!I18+'予算入力シート（SFF）'!I19 -> 678000 | J15: ='予算入力シート（SFF）'!J15+'予算入力シート（SFF）'!J16+'予算入力シート（SFF）'!J17+'予算入力シート（SFF）'!J18+'予算入力シート（SFF）'!J19 -> 660000 | K15: ='予算入力シート（SFF）'!K15+'予算入力シート（SFF）'!K16+'予算入力シート（SFF）'!K17+'予算入力シート（SFF）'!K18+'予算入力シート（SFF）'!K19 -> 0 | ... O15: ='予算入力シート（SFF）'!O15+'予算入力シート（SFF）'!O16+'予算入力シート（SFF）'!O17+'予算入力シート（SFF）'!O18+'予算入力シート（SFF）'!O19 -> 0 | P15: =SUM(D15:O15) -> 1338000 | S15: =S14+1 -> 10 | T15: 決済手数料 | U15: 2138 | V15: =P36/1000 -> 367.2 | W15: =V15/U15 -> 0.1717493
B16: =B15+1 -> 11 | C16: 仕入高 | D16: ='予算入力シート（SFF）'!D20 -> 0 | E16: ='予算入力シート（SFF）'!E20 -> 0 | F16: ='予算入力シート（SFF）'!F20 -> 0 | G16: ='予算入力シート（SFF）'!G20 -> 0 | H16: ='予算入力シート（SFF）'!H20 -> 0 | I16: ='予算入力シート（SFF）'!I20 -> 1050000 | J16: ='予算入力シート（SFF）'!J20 -> 1350000 | K16: ='予算入力シート（SFF）'!K20 -> 0 | ... O16: ='予算入力シート（SFF）'!O20 -> 0 | P16: =SUM(D16:O16) -> 2400000 | T16: 売上原価 | U16: =SUM(U11:U15) -> 27281 | V16: =SUM(V11:V15) -> 36723.46 | W16: =V16/U16 -> 1.3461185
B17: =B16+1 -> 12 | C17: SFF業務委託費 | D17: ='予算入力シート（SFF）'!D21+'予算入力シート（SFF）'!D22+'予算入力シート（SFF）'!D23+'予算入力シート（SFF）'!D24+'予算入力シート（SFF）'!D25+'予算入力シート（SFF）'!D26 -> 0 | E17: ='予算入力シート（SFF）'!E21+'予算入力シート（SFF）'!E22+'予算入力シート（SFF）'!E23+'予算入力シート（SFF）'!E24+'予算入力シート（SFF）'!E25+'予算入力シート（SFF）'!E26 -> 0 | F17: ='予算入力シート（SFF）'!F21+'予算入力シート（SFF）'!F22+'予算入力シート（SFF）'!F23+'予算入力シート（SFF）'!F24+'予算入力シート（SFF）'!F25+'予算入力シート（SFF）'!F26 -> 0 | G17: ='予算入力シート（SFF）'!G21+'予算入力シート（SFF）'!G22+'予算入力シート（SFF）'!G23+'予算入力シート（SFF）'!G24+'予算入力シート（SFF）'!G25+'予算入力シート（SFF）'!G26 -> 0 | H17: ='予算入力シート（SFF）'!H21+'予算入力シート（SFF）'!H22+'予算入力シート（SFF）'!H23+'予算入力シート（SFF）'!H24+'予算入力シート（SFF）'!H25+'予算入力シート（SFF）'!H26 -> 0 | I17: ='予算入力シート（SFF）'!I21+'予算入力シート（SFF）'!I22+'予算入力シート（SFF）'!I23+'予算入力シート（SFF）'!I24+'予算入力シート（SFF）'!I25+'予算入力シート（SFF）'!I26 -> 5860000 | J17: ='予算入力シート（SFF）'!J21+'予算入力シート（SFF）'!J22+'予算入力シート（SFF）'!J23+'予算入力シート（SFF）'!J24+'予算入力シート（SFF）'!J25+'予算入力シート（SFF）'!J26 -> 11170000 | K17: ='予算入力シート（SFF）'!K21+'予算入力シート（SFF）'!K22+'予算入力シート（SFF）'!K23+'予算入力シート（SFF）'!K24+'予算入力シート（SFF）'!K25+'予算入力シート（SFF）'!K26 -> 0 | ... O17: ='予算入力シート（SFF）'!O21+'予算入力シート（SFF）'!O22+'予算入力シート（SFF）'!O23+'予算入力シート（SFF）'!O24+'予算入力シート（SFF）'!O25+'予算入力シート（SFF）'!O26 -> 0 | P17: =SUM(D17:O17) -> 17030000 | T17: 粗利益 | U17: =U10-U16 -> 82329 | V17: =V10-V16 -> 53551.54 | W17: =V17/U17 -> 0.6504578
B18: =B17+1 -> 13 | C18: 備品・消耗品費 | D18: ='予算入力シート（SFF）'!D27+'予算入力シート（SFF）'!D29+'予算入力シート（SFF）'!D30+'予算入力シート（SFF）'!D34 -> 0 | E18: ='予算入力シート（SFF）'!E27+'予算入力シート（SFF）'!E29+'予算入力シート（SFF）'!E30+'予算入力シート（SFF）'!E34 -> 0 | F18: ='予算入力シート（SFF）'!F27+'予算入力シート（SFF）'!F29+'予算入力シート（SFF）'!F30+'予算入力シート（SFF）'!F34 -> 0 | G18: ='予算入力シート（SFF）'!G27+'予算入力シート（SFF）'!G29+'予算入力シート（SFF）'!G30+'予算入力シート（SFF）'!G34 -> 0 | H18: ='予算入力シート（SFF）'!H27+'予算入力シート（SFF）'!H29+'予算入力シート（SFF）'!H30+'予算入力シート（SFF）'!H34 -> 0 | I18: ='予算入力シート（SFF）'!I27+'予算入力シート（SFF）'!I29+'予算入力シート（SFF）'!I30+'予算入力シート（SFF）'!I34 -> 910000 | J18: ='予算入力シート（SFF）'!J27+'予算入力シート（SFF）'!J29+'予算入力シート（SFF）'!J30+'予算入力シート（SFF）'!J34 -> 910000 | K18: ='予算入力シート（SFF）'!K27+'予算入力シート（SFF）'!K29+'予算入力シート（SFF）'!K30+'予算入力シート（SFF）'!K34 -> 0 | ... O18: ='予算入力シート（SFF）'!O27+'予算入力シート（SFF）'!O29+'予算入力シート（SFF）'!O30+'予算入力シート（SFF）'!O34 -> 0 | P18: =SUM(D18:O18) -> 1820000 | T18: 粗利益率(%) | U18: =U17/U10 -> 0.75110848 | V18: =V17/V10 -> 0.59320454 | W18: -%
B19: =B18+1 -> 14 | C19: 会議費 | D19: ='予算入力シート（SFF）'!D28 -> 0 | E19: ='予算入力シート（SFF）'!E28 -> 0 | F19: ='予算入力シート（SFF）'!F28 -> 0 | G19: ='予算入力シート（SFF）'!G28 -> 0 | H19: ='予算入力シート（SFF）'!H28 -> 0 | I19: ='予算入力シート（SFF）'!I28 -> 3113100 | J19: ='予算入力シート（SFF）'!J28 -> 4795160 | K19: ='予算入力シート（SFF）'!K28 -> 0 | ... O19: ='予算入力シート（SFF）'!O28 -> 0 | P19: =SUM(D19:O19) -> 7908260 | T19: 販管費 | U19: 85970 | V19: =P55/1000 -> 70706.051 | W19: =V19/U19 -> 0.82245028
B20: =B19+1 -> 15 | C20: 荷造運賃 | D20: ='予算入力シート（SFF）'!D31 -> 0 | E20: ='予算入力シート（SFF）'!E31 -> 0 | F20: ='予算入力シート（SFF）'!F31 -> 0 | G20: ='予算入力シート（SFF）'!G31 -> 0 | H20: ='予算入力シート（SFF）'!H31 -> 0 | I20: ='予算入力シート（SFF）'!I31 -> 150000 | J20: ='予算入力シート（SFF）'!J31 -> 600000 | K20: ='予算入力シート（SFF）'!K31 -> 0 | ... O20: ='予算入力シート（SFF）'!O31 -> 0 | P20: =SUM(D20:O20) -> 750000 | T20: 営業利益 | U20: =U17-U19 -> -3641 | V20: =V17-V19 -> -17154.511
B21: =B20+1 -> 16 | C21: 接待交際費 | D21: ='予算入力シート（SFF）'!D32 -> 0 | E21: ='予算入力シート（SFF）'!E32 -> 0 | F21: ='予算入力シート（SFF）'!F32 -> 0 | G21: ='予算入力シート（SFF）'!G32 -> 0 | H21: ='予算入力シート（SFF）'!H32 -> 0 | I21: ='予算入力シート（SFF）'!I32 -> 60000 | J21: ='予算入力シート（SFF）'!J32 -> 60000 | K21: ='予算入力シート（SFF）'!K32 -> 0 | ... O21: ='予算入力シート（SFF）'!O32 -> 0 | P21: =SUM(D21:O21) -> 120000
B22: =B21+1 -> 17 | C22: 通信費 | D22: ='予算入力シート（SFF）'!D33 -> 0 | E22: ='予算入力シート（SFF）'!E33 -> 0 | F22: ='予算入力シート（SFF）'!F33 -> 0 | G22: ='予算入力シート（SFF）'!G33 -> 0 | H22: ='予算入力シート（SFF）'!H33 -> 0 | I22: ='予算入力シート（SFF）'!I33 -> 0 | J22: ='予算入力シート（SFF）'!J33 -> 0 | K22: ='予算入力シート（SFF）'!K33 -> 0 | ... O22: ='予算入力シート（SFF）'!O33 -> 0 | P22: =SUM(D22:O22) -> 0
C23: 原価合計 | D23: =SUM(D15:D22) -> 0 | E23: =SUM(E15:E22) -> 0 | F23: =SUM(F15:F22) -> 0 | G23: =SUM(G15:G22) -> 0 | H23: =SUM(H15:H22) -> 0 | I23: =SUM(I15:I22) -> 11821100 | J23: =SUM(J15:J22) -> 19545160 | K23: =SUM(K15:K22) -> 0 | ... O23: =SUM(O15:O22) -> 0 | P23: =SUM(D23:O23) -> 31366260
A24: ① | C24: SFF粗利益 | D24: =D14-D23 -> 0 | E24: =E14-E23 -> 0 | F24: =F14-F23 -> 0 | G24: =G14-G23 -> 0 | H24: =H14-H23 -> 0 | I24: =I14-I23 -> 8821400 | J24: =J14-J23 -> 8197340 | K24: =K14-K23 -> 0 | ... O24: =O14-O23 -> 0 | P24: =SUM(D24:O24) -> 17018740
B26: Ⅱ.定常事業
B27: =B22+1 -> 18 | C27: YouTube事業売上 | D27: ='予算入力シート（YouTube※アパレル、フィットネス)'!D8 -> 2000000 | E27: ='予算入力シート（YouTube※アパレル、フィットネス)'!E8 -> 2050000 | F27: ='予算入力シート（YouTube※アパレル、フィットネス)'!F8 -> 2480000 | G27: ='予算入力シート（YouTube※アパレル、フィットネス)'!G8 -> 4000000 | H27: ='予算入力シート（YouTube※アパレル、フィットネス)'!H8 -> 3260000 | I27: ='予算入力シート（YouTube※アパレル、フィットネス)'!I8 -> 2930000 | J27: ='予算入力シート（YouTube※アパレル、フィットネス)'!J8 -> 2400000 | K27: ='予算入力シート（YouTube※アパレル、フィットネス)'!K8 -> 1930000 | ... O27: ='予算入力シート（YouTube※アパレル、フィットネス)'!O8 -> 1930000 | P27: =SUM(D27:O27) -> 30190000
B28: =B27+1 -> 19 | C28: フィットネス事業売上 | D28: ='予算入力シート（YouTube※アパレル、フィットネス)'!D33 -> 600000 | E28: ='予算入力シート（YouTube※アパレル、フィットネス)'!E33 -> 600000 | F28: ='予算入力シート（YouTube※アパレル、フィットネス)'!F33 -> 600000 | G28: ='予算入力シート（YouTube※アパレル、フィットネス)'!G33 -> 600000 | H28: ='予算入力シート（YouTube※アパレル、フィットネス)'!H33 -> 600000 | I28: ='予算入力シート（YouTube※アパレル、フィットネス)'!I33 -> 600000 | J28: ='予算入力シート（YouTube※アパレル、フィットネス)'!J33 -> 600000 | K28: ='予算入力シート（YouTube※アパレル、フィットネス)'!K33 -> 500000 | ... O28: ='予算入力シート（YouTube※アパレル、フィットネス)'!O33 -> 2000000 | P28: =SUM(D28:O28) -> 7700000
B29: =B28+1 -> 20 | C29: フィットネス事業売上（FC収入） | D29: ='予算入力シート（YouTube※アパレル、フィットネス)'!D34 -> 400000 | E29: ='予算入力シート（YouTube※アパレル、フィットネス)'!E34 -> 400000 | F29: ='予算入力シート（YouTube※アパレル、フィットネス)'!F34 -> 450000 | G29: ='予算入力シート（YouTube※アパレル、フィットネス)'!G34 -> 600000 | H29: ='予算入力シート（YouTube※アパレル、フィットネス)'!H34 -> 650000 | I29: ='予算入力シート（YouTube※アパレル、フィットネス)'!I34 -> 0 | J29: ='予算入力シート（YouTube※アパレル、フィットネス)'!J34 -> 0 | K29: ='予算入力シート（YouTube※アパレル、フィットネス)'!K34 -> 0 | ... O29: ='予算入力シート（YouTube※アパレル、フィットネス)'!O34 -> 0 | P29: =SUM(D29:O29) -> 2500000
B30: =B29+1 -> 21 | C30: アパレル売上 | D30: ='予算入力シート（YouTube※アパレル、フィットネス)'!D34 -> 400000 | E30: ='予算入力シート（YouTube※アパレル、フィットネス)'!E7 -> 100000 | F30: ='予算入力シート（YouTube※アパレル、フィットネス)'!F7 -> 100000 | G30: ='予算入力シート（YouTube※アパレル、フィットネス)'!G7 -> 100000 | H30: ='予算入力シート（YouTube※アパレル、フィットネス)'!H7 -> 100000 | I30: ='予算入力シート（YouTube※アパレル、フィットネス)'!I7 -> 100000 | J30: ='予算入力シート（YouTube※アパレル、フィットネス)'!J7 -> 100000 | K30: ='予算入力シート（YouTube※アパレル、フィットネス)'!K7 -> 100000 | L30: ='予算入力シート（YouTube※アパレル、フィットネス)'!L7 -> 100000 | ... O30: ='予算入力シート（YouTube※アパレル、フィットネス)'!O7 -> 100000 | P30: =SUM(D30:O30) -> 1500000
C31: 売上合計 | D31: =SUM(D27:D30) -> 3400000 | E31: =SUM(E27:E30) -> 3150000 | F31: =SUM(F27:F30) -> 3630000 | G31: =SUM(G27:G30) -> 5300000 | H31: =SUM(H27:H30) -> 4610000 | I31: =SUM(I27:I30) -> 3630000 | J31: =SUM(J27:J30) -> 3100000 | K31: =SUM(K27:K30) -> 2530000 | ... O31: =SUM(O27:O30) -> 4030000 | P31: =SUM(D31:O31) -> 41890000
B32: =B30+1 -> 22 | C32: YouTube経費 | D32: ='予算入力シート（YouTube※アパレル、フィットネス)'!D9 -> 0 | E32: ='予算入力シート（YouTube※アパレル、フィットネス)'!E9 -> 0 | F32: ='予算入力シート（YouTube※アパレル、フィットネス)'!F9 -> 0 | G32: ='予算入力シート（YouTube※アパレル、フィットネス)'!G9 -> 0 | H32: ='予算入力シート（YouTube※アパレル、フィットネス)'!H9 -> 0 | I32: ='予算入力シート（YouTube※アパレル、フィットネス)'!I9 -> 0 | J32: ='予算入力シート（YouTube※アパレル、フィットネス)'!J9 -> 0 | K32: ='予算入力シート（YouTube※アパレル、フィットネス)'!K9 -> 0 | ... O32: ='予算入力シート（YouTube※アパレル、フィットネス)'!O9 -> 0 | P32: =SUM(D32:O32) -> 0
B33: =B32+1 -> 23 | C33: YouTube業務委託費 | D33: ='予算入力シート（YouTube※アパレル、フィットネス)'!D10 -> 0 | E33: ='予算入力シート（YouTube※アパレル、フィットネス)'!E10 -> 0 | F33: ='予算入力シート（YouTube※アパレル、フィットネス)'!F10 -> 0 | G33: ='予算入力シート（YouTube※アパレル、フィットネス)'!G10 -> 0 | H33: ='予算入力シート（YouTube※アパレル、フィットネス)'!H10 -> 0 | I33: ='予算入力シート（YouTube※アパレル、フィットネス)'!I10 -> 0 | J33: ='予算入力シート（YouTube※アパレル、フィットネス)'!J10 -> 0 | K33: ='予算入力シート（YouTube※アパレル、フィットネス)'!K10 -> 0 | ... O33: ='予算入力シート（YouTube※アパレル、フィットネス)'!O10 -> 0 | P33: =SUM(D33:O33) -> 0
B34: =B33+1 -> 24 | C34: アパレル仕入高 | D34: ='予算入力シート（YouTube※アパレル、フィットネス)'!D11 -> 0 | E34: ='予算入力シート（YouTube※アパレル、フィットネス)'!E11 -> 0 | F34: ='予算入力シート（YouTube※アパレル、フィットネス)'!F11 -> 0 | G34: ='予算入力シート（YouTube※アパレル、フィットネス)'!G11 -> 0 | H34: ='予算入力シート（YouTube※アパレル、フィットネス)'!H11 -> 0 | I34: ='予算入力シート（YouTube※アパレル、フィットネス)'!I11 -> 0 | J34: ='予算入力シート（YouTube※アパレル、フィットネス)'!J11 -> 0 | K34: ='予算入力シート（YouTube※アパレル、フィットネス)'!K11 -> 0 | ... O34: ='予算入力シート（YouTube※アパレル、フィットネス)'!O11 -> 0 | P34: =SUM(D34:O34) -> 0
B35: =B34+1 -> 25 | C35: フィットネス業務委託費 | D35: ='予算入力シート（YouTube※アパレル、フィットネス)'!D36 -> 370000 | E35: ='予算入力シート（YouTube※アパレル、フィットネス)'!E36 -> 420000 | F35: ='予算入力シート（YouTube※アパレル、フィットネス)'!F36 -> 420000 | G35: ='予算入力シート（YouTube※アパレル、フィットネス)'!G36 -> 420000 | H35: ='予算入力シート（YouTube※アパレル、フィットネス)'!H36 -> 420000 | I35: ='予算入力シート（YouTube※アパレル、フィットネス)'!I36 -> 420000 | J35: ='予算入力シート（YouTube※アパレル、フィットネス)'!J36 -> 420000 | K35: ='予算入力シート（YouTube※アパレル、フィットネス)'!K36 -> 420000 | ... O35: ='予算入力シート（YouTube※アパレル、フィットネス)'!O36 -> 420000 | P35: =SUM(D35:O35) -> 4990000
B36: =B35+1 -> 26 | C36: 決済手数料 | D36: ='予算入力シート（YouTube※アパレル、フィットネス)'!D37 -> 36000 | E36: ='予算入力シート（YouTube※アパレル、フィットネス)'!E37 -> 36000 | F36: ='予算入力シート（YouTube※アパレル、フィットネス)'!F37 -> 37800 | G36: ='予算入力シート（YouTube※アパレル、フィットネス)'!G37 -> 43200 | H36: ='予算入力シート（YouTube※アパレル、フィットネス)'!H37 -> 45000 | I36: ='予算入力シート（YouTube※アパレル、フィットネス)'!I37 -> 21600 | J36: ='予算入力シート（YouTube※アパレル、フィットネス)'!J37 -> 21600 | K36: ='予算入力シート（YouTube※アパレル、フィットネス)'!K37 -> 18000 | ... O36: ='予算入力シート（YouTube※アパレル、フィットネス)'!O37 -> 72000 | P36: =SUM(D36:O36) -> 367200
C37: 原価合計 | D37: =SUM(D32:D36) -> 406000 | E37: =SUM(E32:E36) -> 456000 | F37: =SUM(F32:F36) -> 457800 | G37: =SUM(G32:G36) -> 463200 | H37: =SUM(H32:H36) -> 465000 | I37: =SUM(I32:I36) -> 441600 | J37: =SUM(J32:J36) -> 441600 | K37: =SUM(K32:K36) -> 438000 | ... O37: =SUM(O32:O36) -> 492000 | P37: =SUM(D37:O37) -> 5357200
A38: ② | C38: 定常事業粗利益 | D38: =D31-D37 -> 2994000 | E38: =E31-E37 -> 2694000 | F38: =F31-F37 -> 3172200 | G38: =G31-G37 -> 4836800 | H38: =H31-H37 -> 4145000 | I38: =I31-I37 -> 3188400 | J38: =J31-J37 -> 2658400 | K38: =K31-K37 -> 2092000 | ... O38: =O31-O37 -> 3538000 | P38: =SUM(D38:O38) -> 36532800
B40: Ⅲ.共通部門
B41: 27 | C41: 本部人件費 | D41: ='予算入力シート（管理部予算）'!D40 -> 2682000 | E41: ='予算入力シート（管理部予算）'!E40 -> 2682000 | F41: ='予算入力シート（管理部予算）'!F40 -> 2682000 | G41: ='予算入力シート（管理部予算）'!G40 -> 2682000 | H41: ='予算入力シート（管理部予算）'!H40 -> 2682000 | I41: ='予算入力シート（管理部予算）'!I40 -> 2682000 | J41: ='予算入力シート（管理部予算）'!J40 -> 2682000 | K41: ='予算入力シート（管理部予算）'!K40 -> 2682000 | ... O41: ='予算入力シート（管理部予算）'!O40 -> 2682000 | P41: =SUM(D41:O41) -> 32184000
B42: =B41+1 -> 28 | C42: 業務委託料 | D42: ='予算入力シート（管理部予算）'!D41+'予算入力シート（YouTube※アパレル、フィットネス)'!D16+'予算入力シート（YouTube※アパレル、フィットネス)'!D42 -> 2360000 | E42: ='予算入力シート（管理部予算）'!E41+'予算入力シート（YouTube※アパレル、フィットネス)'!E16+'予算入力シート（YouTube※アパレル、フィットネス)'!E42 -> 2310000 | F42: ='予算入力シート（管理部予算）'!F41+'予算入力シート（YouTube※アパレル、フィットネス)'!F16+'予算入力シート（YouTube※アパレル、フィットネス)'!F42 -> 2310000 | G42: ='予算入力シート（管理部予算）'!G41+'予算入力シート（YouTube※アパレル、フィットネス)'!G16+'予算入力シート（YouTube※アパレル、フィットネス)'!G42 -> 2310000 | H42: ='予算入力シート（管理部予算）'!H41+'予算入力シート（YouTube※アパレル、フィットネス)'!H16+'予算入力シート（YouTube※アパレル、フィットネス)'!H42 -> 2410000 | I42: ='予算入力シート（管理部予算）'!I41+'予算入力シート（YouTube※アパレル、フィットネス)'!I16+'予算入力シート（YouTube※アパレル、フィットネス)'!I42 -> 2060000 | J42: ='予算入力シート（管理部予算）'!J41+'予算入力シート（YouTube※アパレル、フィットネス)'!J16+'予算入力シート（YouTube※アパレル、フィットネス)'!J42 -> 2060000 | K42: ='予算入力シート（管理部予算）'!K41+'予算入力シート（YouTube※アパレル、フィットネス)'!K16+'予算入力シート（YouTube※アパレル、フィットネス)'!K42 -> 2060000 | ... O42: ='予算入力シート（管理部予算）'!O41+'予算入力シート（YouTube※アパレル、フィットネス)'!O16+'予算入力シート（YouTube※アパレル、フィットネス)'!O42 -> 2060000 | P42: =SUM(D42:O42) -> 26180000
...

Sheet 予算入力シート（YouTube※アパレル、フィットネス)
B1: ◆2026年2月期(計画) | D1: 計画 | E1: 計画 | F1: 計画 | G1: 計画 | H1: 計画 | I1: 計画 | J1: 計画 | K1: 計画 | L1: 計画 | M1: 計画 | N1: 計画 | O1: 計画
D2: =YEAR(#REF!)&MONTH(#REF!) -> #REF! | E2: =YEAR(#REF!)&MONTH(#REF!) -> #REF! | F2: =YEAR(#REF!)&MONTH(#REF!) -> #REF! | G2: =YEAR(#REF!)&MONTH(#REF!) -> #REF! | H2: =YEAR(#REF!)&MONTH(#REF!) -> #REF! | I2: =YEAR(#REF!)&MONTH(#REF!) -> #REF! | J2: =YEAR(#REF!)&MONTH(#REF!) -> #REF! | K2: =YEAR(#REF!)&MONTH(#REF!) -> #REF! | ... O2: =YEAR(#REF!)&MONTH(#REF!) -> #REF!
B4: Ⅰ.YouTube事業 | D4: 46112 | E4: =EOMONTH(D4,1) -> 46142 | F4: =EOMONTH(E4,1) -> 46173 | G4: =EOMONTH(F4,1) -> 46203 | H4: =EOMONTH(G4,1) -> 46234 | I4: =EOMONTH(H4,1) -> 46265 | J4: =EOMONTH(I4,1) -> 46295 | K4: =EOMONTH(J4,1) -> 46326 | L4: =EOMONTH(K4,1) -> 46356 | ... O4: =EOMONTH(N4,1) -> 46446
B5: 1 | C5: 案件収益 | D5: 1400000 | E5: 1400000 | F5: 1800000 | G5: 2300000 | H5: 2300000 | I5: 2300000 | J5: 1800000 | K5: 1400000 | L5: 2300000 | M5: 1800000 | N5: 1400000 | O5: 1400000 | P5: =SUM(D5:O5) -> 21600000 | Q5: VITAS様：100万、極洋様：10万、VEATM様：30万（月）、 Vanquishコード売り上げた分コミュッション制、ヒューロン様：10万 単発案件（YT90万：6・7・8・11月）、（IG40万：5月、9月、12月）
B6: =B5+1 -> 2 | C6: 広告収益 | D6: 500000 | E6: 550000 | F6: 580000 | G6: 1600000 | H6: 860000 | I6: 530000 | J6: 500000 | K6: 430000 | L6: 410000 | M6: 650000 | N6: 350000 | O6: 430000 | P6: =SUM(D6:O6) -> 7390000
B7: =B6+1 -> 3 | C7: アパレル売上高 | D7: 100000 | E7: 100000 | F7: 100000 | G7: 100000 | H7: 100000 | I7: 100000 | J7: 100000 | K7: 100000 | L7: 100000 | M7: 100000 | N7: 100000 | O7: 100000 | P7: =SUM(D7:O7) -> 1200000
A8: ① | C8: 売上合計 | D8: =SUM(D5:D7) -> 2000000 | E8: =SUM(E5:E7) -> 2050000 | F8: =SUM(F5:F7) -> 2480000 | G8: =SUM(G5:G7) -> 4000000 | H8: =SUM(H5:H7) -> 3260000 | I8: =SUM(I5:I7) -> 2930000 | J8: =SUM(J5:J7) -> 2400000 | K8: =SUM(K5:K7) -> 1930000 | ... O8: =SUM(O5:O7) -> 1930000 | P8: =SUM(D8:O8) -> 30190000
B9: =B6+1 -> 3 | C9: YouTube経費 | D9: 0 | E9: 0 | F9: 0 | G9: 0 | H9: 0 | I9: 0 | J9: 0 | K9: 0 | L9: 0 | M9: 0 | N9: 0 | O9: 0 | P9: =SUM(D9:O9) -> 0 | Q9: 現状なし
B10: =B9+1 -> 4 | C10: YouTube業務委託費 | D10: 0 | E10: 0 | F10: 0 | G10: 0 | H10: 0 | I10: 0 | J10: 0 | K10: 0 | L10: 0 | M10: 0 | N10: 0 | O10: 0 | P10: =SUM(D10:O10) -> 0 | Q10: 現状なし
B11: =B10+1 -> 5 | C11: アパレル仕入高 | D11: 0 | E11: 0 | F11: 0 | G11: 0 | H11: 0 | I11: 0 | J11: 0 | K11: 0 | L11: 0 | M11: 0 | N11: 0 | O11: 0 | P11: =SUM(D11:O11) -> 0 | Q11: 仕入れなし
C12: 原価合計 | D12: =SUM(D9:D11) -> 0 | E12: =SUM(E9:E11) -> 0 | F12: =SUM(F9:F11) -> 0 | G12: =SUM(G9:G11) -> 0 | H12: =SUM(H9:H11) -> 0 | I12: =SUM(I9:I11) -> 0 | J12: =SUM(J9:J11) -> 0 | K12: =SUM(K9:K11) -> 0 | ... O12: =SUM(O9:O11) -> 0 | P12: =SUM(D12:O12) -> 0
A13: ② | C13: YouTube事業粗利益 | D13: =D8-D12 -> 2000000 | E13: =E8-E12 -> 2050000 | F13: =F8-F12 -> 2480000 | G13: =G8-G12 -> 4000000 | H13: =H8-H12 -> 3260000 | I13: =I8-I12 -> 2930000 | J13: =J8-J12 -> 2400000 | K13: =K8-K12 -> 1930000 | ... O13: =O8-O12 -> 1930000 | P13: =SUM(D13:O13) -> 30190000
B15: Ⅲ.YouTube販管費
B16: =B11+1 -> 6 | C16: 業務委託料 | D16: 300000 | E16: 300000 | F16: 300000 | G16: 300000 | H16: 400000 | I16: 300000 | J16: 300000 | K16: 300000 | L16: 300000 | M16: 360000 | N16: 300000 | O16: 300000 | P16: =SUM(D16:O16) -> 3760000 | Q16: 編集チーム30万（西銘様、髙島様） 大会編集：7月10万、12月6万（奥谷様）
B17: =B16+1 -> 7 | C17: 通信費 | D17: 2073 | E17: 2073 | F17: 2073 | G17: 2073 | H17: 2073 | I17: 2073 | J17: 2073 | K17: 2073 | L17: 2073 | M17: 2073 | N17: 2073 | O17: 2073 | P17: =SUM(D17:O17) -> 24876 | Q17: YouTubePremium会員費
B18: =B17+1 -> 8 | C18: 地代家賃 | D18: 101391 | E18: 101391 | F18: 101391 | G18: 101391 | H18: 101391 | I18: 101391 | J18: 101391 | K18: 101391 | L18: 101391 | M18: 101391 | N18: 101391 | O18: 101391 | P18: =SUM(D18:O18) -> 1216692 | Q18: アパレルのみ
B19: =B18+1 -> 9 | C19: 支払手数料 | D19: 0 | E19: 0 | F19: 0 | G19: 0 | H19: 0 | I19: 0 | J19: 0 | K19: 0 | L19: 0 | M19: 1000 | N19: 0 | O19: 0 | P19: =SUM(D19:O19) -> 1000 | Q19: 12月PiTaPa維持管理料
B20: =B19+1 -> 10 | C20: リース料 | D20: 57700 | E20: 57700 | F20: 57700 | G20: 57700 | H20: 57700 | I20: 57700 | J20: 57700 | K20: 57700 | L20: 57700 | M20: 0 | N20: 0 | O20: 0 | P20: =SUM(D20:O20) -> 519300 | Q20: 社用車リース代（〜11月）
B21: =B20+1 -> 11 | C21: 会議費 | D21: 3229 | E21: 3229 | F21: 3229 | G21: 3229 | H21: 3229 | I21: 3229 | J21: 3229 | K21: 3229 | L21: 3229 | M21: 3229 | N21: 3229 | O21: 3229 | P21: =SUM(D21:O21) -> 38748
B22: =B21+1 -> 12 | C22: 旅費交通費 | D22: 0 | E22: 0 | F22: 0 | G22: 0 | H22: 0 | I22: 0 | J22: 0 | K22: 0 | L22: 0 | M22: 0 | N22: 0 | O22: 0 | P22: =SUM(D22:O22) -> 0
B23: =B22+1 -> 13 | C23: 広告宣伝費 | D23: 4250.9 | E23: 4250.9 | F23: 4250.9 | G23: 4250.9 | H23: 4250.9 | I23: 4250.9 | J23: 4250.9 | K23: 4250.9 | L23: 4250.9 | M23: 4250.9 | N23: 4250.9 | O23: 4250.9 | P23: =SUM(D23:O23) -> 51010.8
B24: =B23+1 -> 14 | C24: 接待交際費 | D24: 20000 | E24: 20000 | F24: 20000 | G24: 20000 | H24: 20000 | I24: 20000 | J24: 20000 | K24: 20000 | L24: 20000 | M24: 20000 | N24: 20000 | O24: 20000 | P24: =SUM(D24:O24) -> 240000
B25: =B24+1 -> 15 | C25: 備品・消耗品費 | D25: 6196 | E25: 6196 | F25: 6196 | G25: 6196 | H25: 6196 | I25: 6196 | J25: 6196 | K25: 6196 | L25: 6196 | M25: 6196 | N25: 6196 | O25: 6196 | P25: =SUM(D25:O25) -> 74352 | Q25: VITAS (バイタス)サプリメント代
A26: ③ | C26: 販管費合計 | D26: =SUM(D16:D25) -> 494839.9 | E26: =SUM(E16:E25) -> 494839.9 | F26: =SUM(F16:F25) -> 494839.9 | G26: =SUM(G16:G25) -> 494839.9 | H26: =SUM(H16:H25) -> 594839.9 | I26: =SUM(I16:I25) -> 494839.9 | J26: =SUM(J16:J25) -> 494839.9 | K26: =SUM(K16:K25) -> 494839.9 | ... O26: =SUM(O16:O25) -> 437139.9 | P26: =SUM(D26:O26) -> 5925978.8
A28: ①＋②-③ | C28: YouTube営業利益 | D28: =D13-D26 -> 1505160.1 | E28: =E13-E26 -> 1555160.1 | F28: =F13-F26 -> 1985160.1 | G28: =G13-G26 -> 3505160.1 | H28: =H13-H26 -> 2665160.1 | I28: =I13-I26 -> 2435160.1 | J28: =J13-J26 -> 1905160.1 | K28: =K13-K26 -> 1435160.1 | ... O28: =O13-O26 -> 1492860.1 | P28: =SUM(D28:O28) -> 24264021
B32: Ⅰ.フィットネス事業
B33: 1 | C33: フィットネス事業売上 | D33: 600000 | E33: 600000 | F33: 600000 | G33: 600000 | H33: 600000 | I33: 600000 | J33: 600000 | K33: 500000 | L33: 0 | M33: 0 | N33: 1000000 | O33: 2000000 | P33: =SUM(D33:O33) -> 7700000
B34: =B33+1 -> 2 | C34: フィットネス事業売上（FC収入） | D34: 400000 | E34: 400000 | F34: 450000 | G34: 600000 | H34: 650000 | I34: 0 | J34: 0 | K34: 0 | L34: 0 | M34: 0 | N34: 0 | O34: 0 | P34: =SUM(D34:O34) -> 2500000
A35: ① | C35: 売上合計 | D35: =SUM(D33:D34) -> 1000000 | E35: =SUM(E33:E34) -> 1000000 | F35: =SUM(F33:F34) -> 1050000 | G35: =SUM(G33:G34) -> 1200000 | H35: =SUM(H33:H34) -> 1250000 | I35: =SUM(I33:I34) -> 600000 | J35: =SUM(J33:J34) -> 600000 | K35: =SUM(K33:K34) -> 500000 | ... O35: =SUM(O33:O34) -> 2000000 | P35: =SUM(D35:O35) -> 10200000
B36: =B34+1 -> 3 | C36: フィットネス業務委託費 | D36: 370000 | E36: 420000 | F36: 420000 | G36: 420000 | H36: 420000 | I36: 420000 | J36: 420000 | K36: 420000 | L36: 420000 | M36: 420000 | N36: 420000 | O36: 420000 | P36: =SUM(D36:O36) -> 4990000
B37: 4 | C37: 決済手数料 | D37: =D35*0.036 -> 36000 | E37: =E35*0.036 -> 36000 | F37: =F35*0.036 -> 37800 | G37: =G35*0.036 -> 43200 | H37: =H35*0.036 -> 45000 | I37: =I35*0.036 -> 21600 | J37: =J35*0.036 -> 21600 | K37: =K35*0.036 -> 18000 | ... O37: =O35*0.036 -> 72000 | P37: =SUM(D37:O37) -> 367200
C38: 原価合計 | D38: =SUM(D36:D37) -> 406000 | E38: =SUM(E36:E37) -> 456000 | F38: =SUM(F36:F37) -> 457800 | G38: =SUM(G36:G37) -> 463200 | H38: =SUM(H36:H37) -> 465000 | I38: =SUM(I36:I37) -> 441600 | J38: =SUM(J36:J37) -> 441600 | K38: =SUM(K36:K37) -> 438000 | ... O38: =SUM(O36:O37) -> 492000 | P38: =SUM(D38:O38) -> 5357200
A39: ② | C39: フィットネス事業粗利益 | D39: =D35-D38 -> 594000 | E39: =E35-E38 -> 544000 | F39: =F35-F38 -> 592200 | G39: =G35-G38 -> 736800 | H39: =H35-H38 -> 785000 | I39: =I35-I38 -> 158400 | J39: =J35-J38 -> 158400 | K39: =K35-K38 -> 62000 | ... O39: =O35-O38 -> 1508000 | P39: =SUM(D39:O39) -> 4842800
B41: Ⅱ.フィットネス販管費
B42: =B37+1 -> 5 | C42: 業務委託料 | D42: 250000 | E42: 200000 | F42: 200000 | G42: 200000 | H42: 200000 | I42: 200000 | J42: 200000 | K42: 200000 | L42: 200000 | M42: 200000 | N42: 200000 | O42: 200000 | P42: =SUM(D42:O42) -> 2450000 | Q42: 組織コーチング20万＋インスタ運用
B43: =B42+1 -> 6 | C43: 地代家賃 | D43: 208000 | E43: 208000 | F43: 208000 | G43: 208000 | H43: 208000 | I43: 208000 | J43: 208000 | K43: 208000 | L43: 208000 | M43: 208000 | N43: 208000 | O43: 208000 | P43: =SUM(D43:O43) -> 2496000 | Q43: ジム家賃（恭和産業）
B44: =B43+1 -> 7 | C44: 支払手数料 | D44: 0 | E44: 0 | F44: 0 | G44: 0 | H44: 0 | I44: 0 | J44: 0 | K44: 0 | L44: 20800 | M44: 0 | N44: 0 | O44: 0 | P44: =SUM(D44:O44) -> 20800 | Q44: 日本セーフティー㈱10月更新料
B45: =B44+1 -> 8 | C45: 減価償却費 | D45: 32488 | E45: 32488 | F45: 32488 | G45: 32488 | H45: 32488 | I45: 32488 | J45: 32488 | K45: 32488 | L45: 32488 | M45: 32488 | N45: 32488 | O45: 32488 | P45: =SUM(D45:O45) -> 389856
B46: =B45+1 -> 9 | C46: 備品・消耗品費 | D46: 3902 | E46: 3902 | F46: 3902 | G46: 3902 | H46: 3902 | I46: 3902 | J46: 3902 | K46: 3902 | L46: 3902 | M46: 3902 | N46: 3902 | O46: 3902 | P46: =SUM(D46:O46) -> 46824
A47: ③ | C47: 販管費合計 | D47: =SUM(D42:D46) -> 494390 | E47: =SUM(E42:E46) -> 444390 | F47: =SUM(F42:F46) -> 444390 | G47: =SUM(G42:G46) -> 444390 | H47: =SUM(H42:H46) -> 444390 | I47: =SUM(I42:I46) -> 444390 | J47: =SUM(J42:J46) -> 444390 | K47: =SUM(K42:K46) -> 444390 | ... O47: =SUM(O42:O46) -> 444390 | P47: =SUM(D47:O47) -> 5403480
...

Sheet 予算入力シート（MYS）
B1: ◆2026年2月期(計画) | D1: 計画 | E1: 計画 | F1: 計画 | G1: 計画 | H1: 計画 | I1: 計画 | J1: 計画 | K1: 計画 | L1: 計画 | M1: 計画 | N1: 計画 | O1: 計画
D2: 20263 | E2: 20264 | F2: 20265 | G2: 20266 | H2: 20267 | I2: 20268 | J2: 20269 | K2: 202610 | L2: 202611 | M2: 202612 | N2: 20271 | O2: 20272
B4: Ⅰ.MYS売上 | D4: 46112 | E4: =EOMONTH(D4,1) -> 46142 | F4: =EOMONTH(E4,1) -> 46173 | G4: =EOMONTH(F4,1) -> 46203 | H4: =EOMONTH(G4,1) -> 46234 | I4: =EOMONTH(H4,1) -> 46265 | J4: =EOMONTH(I4,1) -> 46295 | K4: =EOMONTH(J4,1) -> 46326 | L4: =EOMONTH(K4,1) -> 46356 | ... O4: =EOMONTH(N4,1) -> 46446
B5: 1 | C5: テスト受講料（スタンダード相当） | D5: 0 | E5: 0 | F5: 0 | G5: 0 | H5: 0 | I5: 0 | J5: 0 | K5: 5775000 | L5: 0 | M5: 0 | N5: 0 | O5: 0 | P5: =SUM(D5:O5) -> 5775000 | Q5: テスト期間は全員同プラン。10月一括計上。15名×385,000円/半年
B6: =B5+1 -> 2 | C6: 卒業後コミュニティ月額 | D6: 0 | E6: 0 | F6: 0 | G6: 0 | H6: 0 | I6: 0 | J6: 0 | K6: 0 | L6: 0 | M6: 0 | N6: 0 | O6: 0 | P6: =SUM(D6:O6) -> 0 | Q6: 本格展開後に設計。今期¥0
A7: ① | C7: 売上合計 | D7: =SUM(D5:D6) -> 0 | E7: =SUM(E5:E6) -> 0 | F7: =SUM(F5:F6) -> 0 | G7: =SUM(G5:G6) -> 0 | H7: =SUM(H5:H6) -> 0 | I7: =SUM(I5:I6) -> 0 | J7: =SUM(J5:J6) -> 0 | K7: =SUM(K5:K6) -> 5775000 | ... O7: =SUM(O5:O6) -> 0 | P7: =SUM(D7:O7) -> 5775000
B8: =B6+1 -> 3 | C8: カリキュラム動画編集費（外注） | D8: 25000 | E8: 25000 | F8: 25000 | G8: 25000 | H8: 25000 | I8: 25000 | J8: 25000 | K8: 37500 | L8: 37500 | M8: 37500 | N8: 37500 | O8: 37500 | P8: =SUM(D8:O8) -> 362500 | Q8: 準備期（3〜9月）：月2本×12,500円 テスト期（10月〜）：月3本×12,500円
B9: =B8+1 -> 4 | C9: ワークシート・提出フォーマット制作 | D9: 0 | E9: 0 | F9: 30000 | G9: 30000 | H9: 10000 | I9: 10000 | J9: 10000 | K9: 15000 | L9: 15000 | M9: 15000 | N9: 10000 | O9: 10000 | P9: =SUM(D9:O9) -> 155000 | Q9: 5〜6月：カリキュラム制作メイン期。テスト期は継続更新分
C10: 原価合計 | D10: =SUM(D8:D9) -> 25000 | E10: =SUM(E8:E9) -> 25000 | F10: =SUM(F8:F9) -> 55000 | G10: =SUM(G8:G9) -> 55000 | H10: =SUM(H8:H9) -> 35000 | I10: =SUM(I8:I9) -> 35000 | J10: =SUM(J8:J9) -> 35000 | K10: =SUM(K8:K9) -> 52500 | ... O10: =SUM(O8:O9) -> 47500 | P10: =SUM(D10:O10) -> 517500
A11: ② | C11: MYS粗利益 | D11: =D7-D10 -> -25000 | E11: =E7-E10 -> -25000 | F11: =F7-F10 -> -55000 | G11: =G7-G10 -> -55000 | H11: =H7-H10 -> -35000 | I11: =I7-I10 -> -35000 | J11: =J7-J10 -> -35000 | K11: =K7-K10 -> 5722500 | ... O11: =O7-O10 -> -47500 | P11: =SUM(D11:O11) -> 5257500
B13: Ⅱ.MYS販管費 | D13: 46112 | E13: =EOMONTH(D4,1) -> 46142 | F13: =EOMONTH(E4,1) -> 46173 | G13: =EOMONTH(F4,1) -> 46203 | H13: =EOMONTH(G4,1) -> 46234 | I13: =EOMONTH(H4,1) -> 46265 | J13: =EOMONTH(I4,1) -> 46295 | K13: =EOMONTH(J4,1) -> 46326 | L13: =EOMONTH(K4,1) -> 46356 | ... O13: =EOMONTH(N4,1) -> 46446
B14: 【人件費・業務委託】
B15: =B9+1 -> 5 | C15: カリキュラム設計委託（かずひら） | D15: 0 | E15: 0 | F15: 150000 | G15: 150000 | H15: 0 | I15: 0 | J15: 0 | K15: 50000 | L15: 50000 | M15: 50000 | N15: 50000 | O15: 50000 | P15: =SUM(D15:O15) -> 550000 | Q15: 5〜6月：カリキュラム作成メイン（月15万） 7〜9月：SFFのためMYS停止 10月〜：テスト監修（月5万）
B16: =B15+1 -> 6 | C16: マネージャー業務委託（1名） | D16: 0 | E16: 0 | F16: 0 | G16: 0 | H16: 0 | I16: 0 | J16: 0 | K16: 350000 | L16: 350000 | M16: 350000 | N16: 350000 | O16: 350000 | P16: =SUM(D16:O16) -> 1750000 | Q16: テスト開始（10月）から計上。時給4,500円×週15h×1.3倍 ≒ 35万円/月
B17: =B16+1 -> 7 | C17: PM・運用スタッフ業務委託（按分） | D17: 0 | E17: 0 | F17: 0 | G17: 0 | H17: 0 | I17: 0 | J17: 0 | K17: 130000 | L17: 130000 | M17: 130000 | N17: 130000 | O17: 130000 | P17: =SUM(D17:O17) -> 650000 | Q17: スタッフ教育開始（10月）から計上。管理部予算との按分。3〜9月は¥0
C18: 人件費・業務委託合計 | D18: =SUM(D15:D17) -> 0 | E18: =SUM(E15:E17) -> 0 | F18: =SUM(F15:F17) -> 150000 | G18: =SUM(G15:G17) -> 150000 | H18: =SUM(H15:H17) -> 0 | I18: =SUM(I15:I17) -> 0 | J18: =SUM(J15:J17) -> 0 | K18: =SUM(K15:K17) -> 530000 | ... O18: =SUM(O15:O17) -> 530000 | P18: =SUM(D18:O18) -> 2950000
B19: 【サービス基盤・制作】
B20: =B17+1 -> 8 | C20: ツール費（UTAGE / 動画PF） | D20: 0 | E20: 0 | F20: 0 | G20: 30000 | H20: 30000 | I20: 30000 | J20: 30000 | K20: 30000 | L20: 30000 | M20: 30000 | N20: 30000 | O20: 30000 | P20: =SUM(D20:O20) -> 270000 | Q20: 6月セットアップ開始。月3万円。プラットフォーム確定後に更新
B21: =B20+1 -> 9 | C21: ツール費（LINE公式） | D21: 0 | E21: 15000 | F21: 15000 | G21: 15000 | H21: 15000 | I21: 15000 | J21: 15000 | K21: 15000 | L21: 15000 | M21: 15000 | N21: 15000 | O21: 15000 | P21: =SUM(D21:O21) -> 165000 | Q21: 4月リスト育成開始に合わせて計上。月1.5万円
B22: =B21+1 -> 10 | C22: ツール費（Zoom・その他） | D22: 0 | E22: 0 | F22: 0 | G22: 5000 | H22: 5000 | I22: 5000 | J22: 5000 | K22: 5000 | L22: 5000 | M22: 5000 | N22: 5000 | O22: 5000 | P22: =SUM(D22:O22) -> 45000 | Q22: Zoom等。月0.5万円。6月〜
B23: =B22+1 -> 11 | C23: LP制作費（外注・10月一括） | D23: 0 | E23: 0 | F23: 0 | G23: 0 | H23: 0 | I23: 0 | J23: 0 | K23: 200000 | L23: 0 | M23: 0 | N23: 0 | O23: 0 | P23: =SUM(D23:O23) -> 200000 | Q23: テスト開始前に発注。15〜30万円レンジ中央値20万円を計上
B24: =B23+1 -> 12 | C24: 決済手数料（3.6%） | D24: 0 | E24: 0 | F24: 0 | G24: 0 | H24: 0 | I24: 0 | J24: 0 | K24: 207900 | L24: 0 | M24: 0 | N24: 0 | O24: 0 | P24: =SUM(D24:O24) -> 207900 | Q24: UTAGE/Stripe等。売上5,775,000円×3.6% ≒ 208千円（10月）
B25: =B24+1 -> 13 | C25: 法務整備費（5月一括） | D25: 0 | E25: 0 | F25: 75000 | G25: 0 | H25: 0 | I25: 0 | J25: 0 | K25: 0 | L25: 0 | M25: 0 | N25: 0 | O25: 0 | P25: =SUM(D25:O25) -> 75000 | Q25: 利用規約・特商法・契約書。専門家監修。5〜10万円
C26: サービス基盤・制作合計 | D26: =SUM(D20:D25) -> 0 | E26: =SUM(E20:E25) -> 15000 | F26: =SUM(F20:F25) -> 90000 | G26: =SUM(G20:G25) -> 50000 | H26: =SUM(H20:H25) -> 50000 | I26: =SUM(I20:I25) -> 50000 | J26: =SUM(J20:J25) -> 50000 | K26: =SUM(K20:K25) -> 457900 | ... O26: =SUM(O20:O25) -> 50000 | P26: =SUM(D26:O26) -> 962900
B27: 【集客・リスト育成】
B28: =B25+1 -> 14 | C28: SNS・YouTube発信関連費 | D28: 0 | E28: 0 | F28: 0 | G28: 0 | H28: 0 | I28: 0 | J28: 0 | K28: 0 | L28: 0 | M28: 0 | N28: 0 | O28: 0 | P28: =SUM(D28:O28) -> 0 | Q28: オーガニック発信のみ。外注なし。発生時は備考欄に記入
B29: =B28+1 -> 15 | C29: 広告宣伝費（Instagram等） | D29: 0 | E29: 0 | F29: 0 | G29: 0 | H29: 0 | I29: 0 | J29: 0 | K29: 0 | L29: 0 | M29: 0 | N29: 0 | O29: 0 | P29: =SUM(D29:O29) -> 0 | Q29: テスト段階は¥0。広告に頼らずリスト・SFF参加者への告知で集客
C30: 集客・リスト育成合計 | D30: =SUM(D28:D29) -> 0 | E30: =SUM(E28:E29) -> 0 | F30: =SUM(F28:F29) -> 0 | G30: =SUM(G28:G29) -> 0 | H30: =SUM(H28:H29) -> 0 | I30: =SUM(I28:I29) -> 0 | J30: =SUM(J28:J29) -> 0 | K30: =SUM(K28:K29) -> 0 | ... O30: =SUM(O28:O29) -> 0 | P30: =SUM(D30:O30) -> 0
B31: 【オフライン直接費】
B32: =B29+1 -> 16 | C32: 会場費・場所代 | D32: 0 | E32: 0 | F32: 0 | G32: 0 | H32: 0 | I32: 0 | J32: 0 | K32: 0 | L32: 0 | M32: 0 | N32: 0 | O32: 0 | P32: =SUM(D32:O32) -> 0 | Q32: 自社ジム（本店）使用のため¥0
B33: =B32+1 -> 17 | C33: 旅費・交通費（コーチング対応） | D33: 5000 | E33: 5000 | F33: 3000 | G33: 3000 | H33: 3000 | I33: 3000 | J33: 3000 | K33: 5000 | L33: 5000 | M33: 5000 | N33: 3000 | O33: 3000 | P33: =SUM(D33:O33) -> 46000 | Q33: 3〜4月オフラインテスト期・10月以降セッション対応分
C34: オフライン直接費合計 | D34: =SUM(D32:D33) -> 5000 | E34: =SUM(E32:E33) -> 5000 | F34: =SUM(F32:F33) -> 3000 | G34: =SUM(G32:G33) -> 3000 | H34: =SUM(H32:H33) -> 3000 | I34: =SUM(I32:I33) -> 3000 | J34: =SUM(J32:J33) -> 3000 | K34: =SUM(K32:K33) -> 5000 | ... O34: =SUM(O32:O33) -> 3000 | P34: =SUM(D34:O34) -> 46000
B35: 【その他販管費】
B36: =B33+1 -> 18 | C36: 備品・消耗品費 | D36: 5000 | E36: 5000 | F36: 5000 | G36: 5000 | H36: 5000 | I36: 5000 | J36: 5000 | K36: 5000 | L36: 5000 | M36: 5000 | N36: 5000 | O36: 5000 | P36: =SUM(D36:O36) -> 60000 | Q36: 月0.5万円 仮計上
B37: =B36+1 -> 19 | C37: 予備費・雑費 | D37: 10000 | E37: 10000 | F37: 10000 | G37: 10000 | H37: 10000 | I37: 10000 | J37: 10000 | K37: 30000 | L37: 30000 | M37: 30000 | N37: 30000 | O37: 30000 | P37: =SUM(D37:O37) -> 220000 | Q37: 準備期1万/月 テスト期3万/月
C38: その他販管費合計 | D38: =SUM(D36:D37) -> 15000 | E38: =SUM(E36:E37) -> 15000 | F38: =SUM(F36:F37) -> 15000 | G38: =SUM(G36:G37) -> 15000 | H38: =SUM(H36:H37) -> 15000 | I38: =SUM(I36:I37) -> 15000 | J38: =SUM(J36:J37) -> 15000 | K38: =SUM(K36:K37) -> 35000 | ... O38: =SUM(O36:O37) -> 35000 | P38: =SUM(D38:O38) -> 280000
A39: ③ | C39: 販管費合計 | D39: =D18+D26+D30+D34+D38 -> 20000 | E39: =E18+E26+E30+E34+E38 -> 35000 | F39: =F18+F26+F30+F34+F38 -> 258000 | G39: =G18+G26+G30+G34+G38 -> 218000 | H39: =H18+H26+H30+H34+H38 -> 68000 | I39: =I18+I26+I30+I34+I38 -> 68000 | J39: =J18+J26+J30+J34+J38 -> 68000 | K39: =K18+K26+K30+K34+K38 -> 1027900 | ... O39: =O18+O26+O30+O34+O38 -> 618000 | P39: =SUM(D39:O39) -> 4238900
A41: ①＋②-③ | C41: MYS営業利益 | D41: =D7-D10-D39 -> -45000 | E41: =E7-E10-E39 -> -60000 | F41: =F7-F10-F39 -> -313000 | G41: =G7-G10-G39 -> -273000 | H41: =H7-H10-H39 -> -103000 | I41: =I7-I10-I39 -> -103000 | J41: =J7-J10-J39 -> -103000 | K41: =K7-K10-K39 -> 4694600 | ... O41: =O7-O10-O39 -> -665500 | P41: =SUM(D41:O41) -> 1018600

Sheet 予算入力シート（SFC）
B1: ◆2026年2月期(計画) | D1: 計画 | E1: 計画 | F1: 計画 | G1: 計画 | H1: 計画 | I1: 計画 | J1: 計画 | K1: 計画 | L1: 計画 | M1: 計画 | N1: 計画 | O1: 計画
D2: =YEAR(#REF!)&MONTH(#REF!) -> #REF! | E2: =YEAR(#REF!)&MONTH(#REF!) -> #REF! | F2: =YEAR(#REF!)&MONTH(#REF!) -> #REF! | G2: =YEAR(#REF!)&MONTH(#REF!) -> #REF! | H2: =YEAR(#REF!)&MONTH(#REF!) -> #REF! | I2: =YEAR(#REF!)&MONTH(#REF!) -> #REF! | J2: =YEAR(#REF!)&MONTH(#REF!) -> #REF! | K2: =YEAR(#REF!)&MONTH(#REF!) -> #REF! | ... O2: =YEAR(#REF!)&MONTH(#REF!) -> #REF!
B4: Ⅰ.SFC事業 | D4: 46112 | E4: =EOMONTH(D4,1) -> 46142 | F4: =EOMONTH(E4,1) -> 46173 | G4: =EOMONTH(F4,1) -> 46203 | H4: =EOMONTH(G4,1) -> 46234 | I4: =EOMONTH(H4,1) -> 46265 | J4: =EOMONTH(I4,1) -> 46295 | K4: =EOMONTH(J4,1) -> 46326 | L4: =EOMONTH(K4,1) -> 46356 | ... O4: =EOMONTH(N4,1) -> 46446
B5: 1 | C5: 月額会費収入 | D5: 0 | E5: 0 | F5: 0 | G5: 0 | H5: 0 | I5: 0 | J5: 0 | K5: 30000 | L5: 54000 | M5: 78000 | N5: 102000 | O5: 126000 | P5: =SUM(D5:O5) -> 390000 | Q5: 月額3,000円×想定会員数（10月10名→月8名純増） テスト期（4〜9月）は無料運用のため売上ゼロ
B6: 2 | C6: イベント参加費（非会員） | D6: 0 | E6: 0 | F6: 0 | G6: 0 | H6: 0 | I6: 0 | J6: 0 | K6: 0 | L6: 0 | M6: 0 | N6: 0 | O6: 0 | P6: =SUM(D6:O6) -> 0 | Q6: 1,500円/回（SFF参加者等非会員向け） 本格化フェーズ以降に計上予定
B7: 3 | C7: その他収入 | D7: 0 | E7: 0 | F7: 0 | G7: 0 | H7: 0 | I7: 0 | J7: 0 | K7: 0 | L7: 0 | M7: 0 | N7: 0 | O7: 0 | P7: =SUM(D7:O7) -> 0 | Q7: 合宿・特別WS等の追加課金 SFF後本格化フェーズ以降に計上予定
A8: ① | C8: 売上合計 | D8: =SUM(D5:D7) -> 0 | E8: =SUM(E5:E7) -> 0 | F8: =SUM(F5:F7) -> 0 | G8: =SUM(G5:G7) -> 0 | H8: =SUM(H5:H7) -> 0 | I8: =SUM(I5:I7) -> 0 | J8: =SUM(J5:J7) -> 0 | K8: =SUM(K5:K7) -> 30000 | ... O8: =SUM(O5:O7) -> 126000 | P8: =SUM(D8:O8) -> 390000
B9: =B6+1 -> 3 | C9: 会議費（イベント実費） | D9: 0 | E9: 10000 | F9: 10000 | G9: 10000 | H9: 10000 | I9: 10000 | J9: 0 | K9: 0 | L9: 0 | M9: 0 | N9: 0 | O9: 0 | P9: =SUM(D9:O9) -> 50000 | Q9: 月1回オフラインイベント実費 （会場費・飲食・備品含む） 1回あたり1万円以内設計。Phase1〜5（4〜8月）
B10: =B9+1 -> 4 | C10: 備品・消耗品費（クリアファイル） | D10: 0 | E10: 0 | F10: 4000 | G10: 0 | H10: 0 | I10: 0 | J10: 0 | K10: 0 | L10: 0 | M10: 0 | N10: 0 | O10: 0 | P10: =SUM(D10:O10) -> 4000 | Q10: 「Shapeの証し」クリアファイル16冊 約250円/冊×16冊。Phase2（5月）に計上
B11: =B10+1 -> 5 | C11: 支払手数料（Stripe 3.6%） | D11: 0 | E11: 0 | F11: 0 | G11: 0 | H11: 0 | I11: 0 | J11: 0 | K11: 1080 | L11: 1944 | M11: 2808 | N11: 3672 | O11: 4536 | P11: =SUM(D11:O11) -> 14040 | Q11: 月額会費収入の3.6% テスト期（無料運用）はゼロ
C12: 原価合計 | D12: =SUM(D9:D11) -> 0 | E12: =SUM(E9:E11) -> 10000 | F12: =SUM(F9:F11) -> 14000 | G12: =SUM(G9:G11) -> 10000 | H12: =SUM(H9:H11) -> 10000 | I12: =SUM(I9:I11) -> 10000 | J12: =SUM(J9:J11) -> 0 | K12: =SUM(K9:K11) -> 1080 | ... O12: =SUM(O9:O11) -> 4536 | P12: =SUM(D12:O12) -> 68040
A13: ② | C13: SFC事業粗利益 | D13: =D8-D12 -> 0 | E13: =E8-E12 -> -10000 | F13: =F8-F12 -> -14000 | G13: =G8-G12 -> -10000 | H13: =H8-H12 -> -10000 | I13: =I8-I12 -> -10000 | J13: =J8-J12 -> 0 | K13: =K8-K12 -> 28920 | ... O13: =O8-O12 -> 121464 | P13: =SUM(D13:O13) -> 321960
B15: Ⅲ.SFC販管費
B16: 7 | C16: 業務委託料（ロゴ・デザイン制作） | D16: 0 | E16: 0 | F16: 0 | G16: 300000 | H16: 50000 | I16: 0 | J16: 0 | K16: 0 | L16: 0 | M16: 0 | N16: 0 | O16: 0 | P16: =SUM(D16:O16) -> 350000 | Q16: IDAさん委託計35万 6月：初回制作30万、7月：最終調整5万
B17: 8 | C17: 業務委託料（運営スタッフ） | D17: 0 | E17: 0 | F17: 0 | G17: 0 | H17: 0 | I17: 0 | J17: 0 | K17: 150000 | L17: 150000 | M17: 150000 | N17: 150000 | O17: 150000 | P17: =SUM(D17:O17) -> 750000 | Q17: 本格化（10月〜）スタッフ2〜3名・業委 最低ライン15万/月で仮置き
B18: 9 | C18: 地代家賃 | D18: 0 | E18: 0 | F18: 0 | G18: 0 | H18: 0 | I18: 0 | J18: 0 | K18: 30000 | L18: 30000 | M18: 30000 | N18: 30000 | O18: 30000 | P18: =SUM(D18:O18) -> 150000 | Q18: 本格化（10月〜）レンタルスペース月1〜2回 テスト期はイベント実費（会議費）に含む
B19: 10 | C19: 通信費 | D19: 0 | E19: 0 | F19: 0 | G19: 0 | H19: 0 | I19: 0 | J19: 0 | K19: 10000 | L19: 10000 | M19: 10000 | N19: 10000 | O19: 10000 | P19: =SUM(D19:O19) -> 50000 | Q19: LINEオープンチャット：無料 Stripe・Salesforce等 本格化（10月〜）1万円/月で仮置き
B20: 11 | C20: 広告宣伝費 | D20: 0 | E20: 0 | F20: 0 | G20: 0 | H20: 0 | I20: 0 | J20: 0 | K20: 30000 | L20: 30000 | M20: 30000 | N20: 30000 | O20: 30000 | P20: =SUM(D20:O20) -> 150000 | Q20: テスト期は外部発信強化しない方針のためゼロ 本格化（10月〜）Instagram広告等：3万/月
B21: 12 | C21: 接待交際費 | D21: 0 | E21: 0 | F21: 0 | G21: 0 | H21: 0 | I21: 10000 | J21: 0 | K21: 0 | L21: 0 | M21: 0 | N21: 0 | O21: 0 | P21: =SUM(D21:O21) -> 10000 | Q21: Phase5（8月）SFF決起会 Part2 ご飯会：1万円
B22: 13 | C22: 備品・消耗品費（名札・付箋等） | D22: 0 | E22: 3000 | F22: 3000 | G22: 3000 | H22: 3000 | I22: 3000 | J22: 0 | K22: 5000 | L22: 5000 | M22: 5000 | N22: 5000 | O22: 5000 | P22: =SUM(D22:O22) -> 40000 | Q22: テスト期：3,000円/月、本格化後：5,000円/月
B23: 14 | C23: 備品・消耗品費（会員証・印刷物） | D23: 0 | E23: 0 | F23: 0 | G23: 0 | H23: 0 | I23: 0 | J23: 0 | K23: 70000 | L23: 0 | M23: 0 | N23: 0 | O23: 0 | P23: =SUM(D23:O23) -> 70000 | Q23: 本格化決定後（10月）一括計上 会員証・印刷物初回100部：7万円
A24: ③ | C24: 販管費合計 | D24: =SUM(D16:D23) -> 0 | E24: =SUM(E16:E23) -> 3000 | F24: =SUM(F16:F23) -> 3000 | G24: =SUM(G16:G23) -> 303000 | H24: =SUM(H16:H23) -> 53000 | I24: =SUM(I16:I23) -> 13000 | J24: =SUM(J16:J23) -> 0 | K24: =SUM(K16:K23) -> 295000 | ... O24: =SUM(O16:O23) -> 225000 | P24: =SUM(D24:O24) -> 1570000
A26: ①＋②-③ | C26: SFCコミュニティ営業利益 | D26: =D13-D24 -> 0 | E26: =E13-E24 -> -13000 | F26: =F13-F24 -> -17000 | G26: =G13-G24 -> -313000 | H26: =H13-H24 -> -63000 | I26: =I13-I24 -> -23000 | J26: =J13-J24 -> 0 | K26: =K13-K24 -> -266080 | ... O26: =O13-O24 -> -103536 | P26: =SUM(D26:O26) -> -1248040

Sheet 予算入力シート（SFF）
B1: ◆2026年2月期(計画) | D1: 計画 | E1: 計画 | F1: 計画 | G1: 計画 | H1: 計画 | I1: 計画 | J1: 計画 | K1: 計画 | L1: 計画 | M1: 計画 | N1: 計画 | O1: 計画 | S1: SFF売上台帳（予測） | W1: ※Ｃ列から選択ください。 | Z1: SFF原価台帳（予測） | AD1: ※A列から選択ください。
D2: =YEAR(D3)&MONTH(D3) -> 20263 | E2: =YEAR(E3)&MONTH(E3) -> 20264 | F2: =YEAR(F3)&MONTH(F3) -> 20265 | G2: =YEAR(G3)&MONTH(G3) -> 20266 | H2: =YEAR(H3)&MONTH(H3) -> 20267 | I2: =YEAR(I3)&MONTH(I3) -> 20268 | J2: =YEAR(J3)&MONTH(J3) -> 20269 | K2: =YEAR(K3)&MONTH(K3) -> 202610 | ... O2: =YEAR(O3)&MONTH(O3) -> 20272
A3: 科目（細） | B3: 事業/科目 | D3: 46112 | E3: =EOMONTH(D3,1) -> 46142 | F3: =EOMONTH(E3,1) -> 46173 | G3: =EOMONTH(F3,1) -> 46203 | H3: =EOMONTH(G3,1) -> 46234 | I3: =EOMONTH(H3,1) -> 46265 | J3: =EOMONTH(I3,1) -> 46295 | K3: =EOMONTH(J3,1) -> 46326 | L3: =EOMONTH(K3,1) -> 46356 | ... O3: =EOMONTH(N3,1) -> 46446 | P3: 合計 | Q3: 備考欄 | S3: 大会発生月 | T3: 大会名 | U3: 入金月 | V3: 取引先/内容 | W3: 科目 | X3: 金額 | Z3: 大会発生月 | AA3: 大会名 | AB3: 支払月 | AC3: 取引先/内容 | AD3: 科目 | AE3: 金額
B4: Ⅰ.SFF | R4: 記載例 | T4: 〇〇 | U4: 46082 | V4: 〇〇 | W4: 協賛売上 | X4: 3000000 | Y4: 記載例 | Z4: 46265 | AA4: 〇〇 | AB4: 46082 | AC4: 〇〇 | AD4: 出場チケット手数料（3.6%) | AE4: 0
B5: 1 | C5: 協賛売上 | D5: =SUMIFS($X:$X,$S:$S,D$3,$W:$W,$C5) -> 0 | E5: =SUMIFS($X:$X,$S:$S,E$3,$W:$W,$C5) -> 0 | F5: =SUMIFS($X:$X,$S:$S,F$3,$W:$W,$C5) -> 0 | G5: =SUMIFS($X:$X,$S:$S,G$3,$W:$W,$C5) -> 0 | H5: =SUMIFS($X:$X,$S:$S,H$3,$W:$W,$C5) -> 0 | I5: =SUMIFS($X:$X,$S:$S,I$3,$W:$W,$C5) -> 1300000 | J5: =SUMIFS($X:$X,$S:$S,J$3,$W:$W,$C5) -> 8400000 | K5: =SUMIFS($X:$X,$S:$S,K$3,$W:$W,$C5) -> 0 | ... O5: =SUMIFS($X:$X,$S:$S,O$3,$W:$W,$C5) -> 0 | P5: =SUM(D5:O5) -> 9700000 | S5: 46295 | T5: 関東大会 | U5: 45901 | W5: 協賛売上 | X5: 0 | Z5: 46295 | AA5: 関東大会 | AB5: 45930 | AD5: 出場チケット手数料(3.6%) | AE5: 0
B6: =B5+1 -> 2 | C6: 来場者売上 | D6: =SUMIFS($X:$X,$S:$S,D$3,$W:$W,$C6) -> 0 | E6: =SUMIFS($X:$X,$S:$S,E$3,$W:$W,$C6) -> 0 | F6: =SUMIFS($X:$X,$S:$S,F$3,$W:$W,$C6) -> 0 | G6: =SUMIFS($X:$X,$S:$S,G$3,$W:$W,$C6) -> 0 | H6: =SUMIFS($X:$X,$S:$S,H$3,$W:$W,$C6) -> 0 | I6: =SUMIFS($X:$X,$S:$S,I$3,$W:$W,$C6) -> 11940000 | J6: =SUMIFS($X:$X,$S:$S,J$3,$W:$W,$C6) -> 11940000 | K6: =SUMIFS($X:$X,$S:$S,K$3,$W:$W,$C6) -> 0 | ... O6: =SUMIFS($X:$X,$S:$S,O$3,$W:$W,$C6) -> 0 | P6: =SUM(D6:O6) -> 23880000 | S6: 46295 | T6: 関東大会 | U6: 45930 | W6: 来場者売上 | X6: 0 | Z6: 46295 | AA6: 関東大会 | AB6: 45930 | AD6: 客席チケット手数料(3.6%) | AE6: 0
B7: =B6+1 -> 3 | C7: 選手 | D7: =SUMIFS($X:$X,$S:$S,D$3,$W:$W,$C7) -> 0 | E7: =SUMIFS($X:$X,$S:$S,E$3,$W:$W,$C7) -> 0 | F7: =SUMIFS($X:$X,$S:$S,F$3,$W:$W,$C7) -> 0 | G7: =SUMIFS($X:$X,$S:$S,G$3,$W:$W,$C7) -> 0 | H7: =SUMIFS($X:$X,$S:$S,H$3,$W:$W,$C7) -> 0 | I7: =SUMIFS($X:$X,$S:$S,I$3,$W:$W,$C7) -> 5033000 | J7: =SUMIFS($X:$X,$S:$S,J$3,$W:$W,$C7) -> 5033000 | K7: =SUMIFS($X:$X,$S:$S,K$3,$W:$W,$C7) -> 0 | ... O7: =SUMIFS($X:$X,$S:$S,O$3,$W:$W,$C7) -> 0 | P7: =SUM(D7:O7) -> 10066000 | S7: 46295 | T7: 関東大会 | U7: 45930 | W7: 選手 | X7: 0 | Z7: 46295 | AA7: 関東大会 | AB7: 45930 | AD7: バックサポートチケット手数料(3.6%) | AE7: 0
B8: =B7+1 -> 4 | C8: バックサポート | D8: =SUMIFS($X:$X,$S:$S,D$3,$W:$W,$C8) -> 0 | E8: =SUMIFS($X:$X,$S:$S,E$3,$W:$W,$C8) -> 0 | F8: =SUMIFS($X:$X,$S:$S,F$3,$W:$W,$C8) -> 0 | G8: =SUMIFS($X:$X,$S:$S,G$3,$W:$W,$C8) -> 0 | H8: =SUMIFS($X:$X,$S:$S,H$3,$W:$W,$C8) -> 0 | I8: =SUMIFS($X:$X,$S:$S,I$3,$W:$W,$C8) -> 1089000 | J8: =SUMIFS($X:$X,$S:$S,J$3,$W:$W,$C8) -> 1089000 | K8: =SUMIFS($X:$X,$S:$S,K$3,$W:$W,$C8) -> 0 | ... O8: =SUMIFS($X:$X,$S:$S,O$3,$W:$W,$C8) -> 0 | P8: =SUM(D8:O8) -> 2178000 | S8: 46295 | T8: 関東大会 | U8: 45930 | W8: バックサポート | X8: 0 | Z8: 46295 | AA8: 関東大会 | AB8: 45930 | AD8: カラーリングチケット手数料(3.2%) | AE8: 0
B9: =B8+1 -> 5 | C9: 物販売上 | D9: =SUMIFS($X:$X,$S:$S,D$3,$W:$W,$C9) -> 0 | E9: =SUMIFS($X:$X,$S:$S,E$3,$W:$W,$C9) -> 0 | F9: =SUMIFS($X:$X,$S:$S,F$3,$W:$W,$C9) -> 0 | G9: =SUMIFS($X:$X,$S:$S,G$3,$W:$W,$C9) -> 0 | H9: =SUMIFS($X:$X,$S:$S,H$3,$W:$W,$C9) -> 0 | I9: =SUMIFS($X:$X,$S:$S,I$3,$W:$W,$C9) -> 400000 | J9: =SUMIFS($X:$X,$S:$S,J$3,$W:$W,$C9) -> 400000 | K9: =SUMIFS($X:$X,$S:$S,K$3,$W:$W,$C9) -> 0 | ... O9: =SUMIFS($X:$X,$S:$S,O$3,$W:$W,$C9) -> 0 | P9: =SUM(D9:O9) -> 800000 | S9: 46295 | T9: 関東大会 | U9: 45930 | W9: 物販売上 | X9: 0 | Z9: 46295 | AA9: 関東大会 | AB9: 45930 | AD9: 動画手数料(3.6%) | AE9: 0
B10: =B9+1 -> 6 | C10: フォトレコ | D10: =SUMIFS($X:$X,$S:$S,D$3,$W:$W,$C10) -> 0 | E10: =SUMIFS($X:$X,$S:$S,E$3,$W:$W,$C10) -> 0 | F10: =SUMIFS($X:$X,$S:$S,F$3,$W:$W,$C10) -> 0 | G10: =SUMIFS($X:$X,$S:$S,G$3,$W:$W,$C10) -> 0 | H10: =SUMIFS($X:$X,$S:$S,H$3,$W:$W,$C10) -> 0 | I10: =SUMIFS($X:$X,$S:$S,I$3,$W:$W,$C10) -> 600000 | J10: =SUMIFS($X:$X,$S:$S,J$3,$W:$W,$C10) -> 600000 | K10: =SUMIFS($X:$X,$S:$S,K$3,$W:$W,$C10) -> 0 | ... O10: =SUMIFS($X:$X,$S:$S,O$3,$W:$W,$C10) -> 0 | P10: =SUM(D10:O10) -> 1200000 | S10: 46295 | T10: 関東大会 | U10: 45930 | W10: フォトレコ | X10: 0 | Z10: 46295 | AA10: 関東大会 | AB10: 45930 | AD10: アパレル仕入れ | AE10: 0
B11: =B10+1 -> 7 | C11: 動画販売 | D11: =SUMIFS($X:$X,$S:$S,D$3,$W:$W,$C11) -> 0 | E11: =SUMIFS($X:$X,$S:$S,E$3,$W:$W,$C11) -> 0 | F11: =SUMIFS($X:$X,$S:$S,F$3,$W:$W,$C11) -> 0 | G11: =SUMIFS($X:$X,$S:$S,G$3,$W:$W,$C11) -> 0 | H11: =SUMIFS($X:$X,$S:$S,H$3,$W:$W,$C11) -> 0 | I11: =SUMIFS($X:$X,$S:$S,I$3,$W:$W,$C11) -> 198000 | J11: =SUMIFS($X:$X,$S:$S,J$3,$W:$W,$C11) -> 198000 | K11: =SUMIFS($X:$X,$S:$S,K$3,$W:$W,$C11) -> 0 | ... O11: =SUMIFS($X:$X,$S:$S,O$3,$W:$W,$C11) -> 0 | P11: =SUM(D11:O11) -> 396000 | S11: 46295 | T11: 関東大会 | U11: 45930 | W11: 動画販売 | X11: 0 | Z11: 46295 | AA11: 関東大会 | AB11: 45930 | AD11: 演出費 | AE11: 0
B12: =B11+1 -> 8 | C12: カラーリング | D12: =SUMIFS($X:$X,$S:$S,D$3,$W:$W,$C12) -> 0 | E12: =SUMIFS($X:$X,$S:$S,E$3,$W:$W,$C12) -> 0 | F12: =SUMIFS($X:$X,$S:$S,F$3,$W:$W,$C12) -> 0 | G12: =SUMIFS($X:$X,$S:$S,G$3,$W:$W,$C12) -> 0 | H12: =SUMIFS($X:$X,$S:$S,H$3,$W:$W,$C12) -> 0 | I12: =SUMIFS($X:$X,$S:$S,I$3,$W:$W,$C12) -> 82500 | J12: =SUMIFS($X:$X,$S:$S,J$3,$W:$W,$C12) -> 82500 | K12: =SUMIFS($X:$X,$S:$S,K$3,$W:$W,$C12) -> 0 | ... O12: =SUMIFS($X:$X,$S:$S,O$3,$W:$W,$C12) -> 0 | P12: =SUM(D12:O12) -> 165000 | S12: 46295 | T12: 関東大会 | U12: 45930 | W12: カラーリング | X12: 0 | Z12: 46295 | AA12: 関東大会 | AB12: 45930 | AD12: 人件費(審査員) | AE12: 0
B13: =B12+1 -> 9 | C13: SFFその他 | D13: =SUMIFS($X:$X,$S:$S,D$3,$W:$W,$C13) -> 0 | E13: =SUMIFS($X:$X,$S:$S,E$3,$W:$W,$C13) -> 0 | F13: =SUMIFS($X:$X,$S:$S,F$3,$W:$W,$C13) -> 0 | G13: =SUMIFS($X:$X,$S:$S,G$3,$W:$W,$C13) -> 0 | H13: =SUMIFS($X:$X,$S:$S,H$3,$W:$W,$C13) -> 0 | I13: =SUMIFS($X:$X,$S:$S,I$3,$W:$W,$C13) -> 0 | J13: =SUMIFS($X:$X,$S:$S,J$3,$W:$W,$C13) -> 0 | K13: =SUMIFS($X:$X,$S:$S,K$3,$W:$W,$C13) -> 0 | ... O13: =SUMIFS($X:$X,$S:$S,O$3,$W:$W,$C13) -> 0 | P13: =SUM(D13:O13) -> 0 | S13: 46295 | T13: 関東大会 | U13: 45930 | W13: SFFその他 | X13: 0 | Z13: 46295 | AA13: 関東大会 | AB13: 45930 | AD13: 人件費(MC) | AE13: 0
C14: 売上合計 | D14: =SUM(D5:D13) -> 0 | E14: =SUM(E5:E13) -> 0 | F14: =SUM(F5:F13) -> 0 | G14: =SUM(G5:G13) -> 0 | H14: =SUM(H5:H13) -> 0 | I14: =SUM(I5:I13) -> 20642500 | J14: =SUM(J5:J13) -> 27742500 | K14: =SUM(K5:K13) -> 0 | ... O14: =SUM(O5:O13) -> 0 | P14: =SUM(D14:O14) -> 48385000 | S14: 46295 | T14: 関東大会 | U14: 45961 | W14: 協賛売上 | X14: 0 | Z14: 46295 | AA14: 関東大会 | AB14: 45930 | AD14: 人件費(カメラ) | AE14: 0
A15: 出場チケット手数料（3.6%) | B15: =B13+1 -> 10 | C15: 支払手数料 | D15: =SUMIFS($AE:$AE,$Z:$Z,D$3,$AD:$AD,$A15) -> 0 | E15: =SUMIFS($AE:$AE,$Z:$Z,E$3,$AD:$AD,$A15) -> 0 | F15: =SUMIFS($AE:$AE,$Z:$Z,F$3,$AD:$AD,$A15) -> 0 | G15: =SUMIFS($AE:$AE,$Z:$Z,G$3,$AD:$AD,$A15) -> 0 | H15: =SUMIFS($AE:$AE,$Z:$Z,H$3,$AD:$AD,$A15) -> 0 | I15: =SUMIFS($AE:$AE,$Z:$Z,I$3,$AD:$AD,$A15) -> 181188 | J15: =SUMIFS($AE:$AE,$Z:$Z,J$3,$AD:$AD,$A15) -> 181188 | K15: =SUMIFS($AE:$AE,$Z:$Z,K$3,$AD:$AD,$A15) -> 0 | ... O15: =SUMIFS($AE:$AE,$Z:$Z,O$3,$AD:$AD,$A15) -> 0 | P15: =SUM(D15:O15) -> 362376 | S15: 46295 | T15: 関東大会 | U15: 45961 | W15: 来場者売上 | X15: 0 | Z15: 46295 | AA15: 関東大会 | AB15: 45930 | AD15: その他外部委託費 | AE15: 210000
A16: 客席チケット手数料（3.6%) | B16: =B15+1 -> 11 | C16: 支払手数料 | D16: =SUMIFS($AE:$AE,$Z:$Z,D$3,$AD:$AD,$A16) -> 0 | E16: =SUMIFS($AE:$AE,$Z:$Z,E$3,$AD:$AD,$A16) -> 0 | F16: =SUMIFS($AE:$AE,$Z:$Z,F$3,$AD:$AD,$A16) -> 0 | G16: =SUMIFS($AE:$AE,$Z:$Z,G$3,$AD:$AD,$A16) -> 0 | H16: =SUMIFS($AE:$AE,$Z:$Z,H$3,$AD:$AD,$A16) -> 0 | I16: =SUMIFS($AE:$AE,$Z:$Z,I$3,$AD:$AD,$A16) -> 447840 | J16: =SUMIFS($AE:$AE,$Z:$Z,J$3,$AD:$AD,$A16) -> 429840 | K16: =SUMIFS($AE:$AE,$Z:$Z,K$3,$AD:$AD,$A16) -> 0 | ... O16: =SUMIFS($AE:$AE,$Z:$Z,O$3,$AD:$AD,$A16) -> 0 | P16: =SUM(D16:O16) -> 877680 | S16: 46295 | T16: 関東大会 | U16: 45961 | W16: 選手 | X16: 0 | Z16: 46295 | AA16: 関東大会 | AB16: 45930 | AD16: 人件費(運営スタッフ) | AE16: 0
A17: バックサポートチケット手数料（3.6%) | B17: =B16+1 -> 12 | C17: 支払手数料 | D17: =SUMIFS($AE:$AE,$Z:$Z,D$3,$AD:$AD,$A17) -> 0 | E17: =SUMIFS($AE:$AE,$Z:$Z,E$3,$AD:$AD,$A17) -> 0 | F17: =SUMIFS($AE:$AE,$Z:$Z,F$3,$AD:$AD,$A17) -> 0 | G17: =SUMIFS($AE:$AE,$Z:$Z,G$3,$AD:$AD,$A17) -> 0 | H17: =SUMIFS($AE:$AE,$Z:$Z,H$3,$AD:$AD,$A17) -> 0 | I17: =SUMIFS($AE:$AE,$Z:$Z,I$3,$AD:$AD,$A17) -> 39204 | J17: =SUMIFS($AE:$AE,$Z:$Z,J$3,$AD:$AD,$A17) -> 39204 | K17: =SUMIFS($AE:$AE,$Z:$Z,K$3,$AD:$AD,$A17) -> 0 | ... O17: =SUMIFS($AE:$AE,$Z:$Z,O$3,$AD:$AD,$A17) -> 0 | P17: =SUM(D17:O17) -> 78408 | S17: 46295 | T17: 関東大会 | U17: 45961 | W17: バックサポート | X17: 0 | Z17: 46295 | AA17: 関東大会 | AB17: 45930 | AD17: メダルトロフィー代 | AE17: 0
A18: カラーリングチケット手数料（3.2%） | B18: =B17+1 -> 13 | C18: 支払手数料 | D18: =SUMIFS($AE:$AE,$Z:$Z,D$3,$AD:$AD,$A18) -> 0 | E18: =SUMIFS($AE:$AE,$Z:$Z,E$3,$AD:$AD,$A18) -> 0 | F18: =SUMIFS($AE:$AE,$Z:$Z,F$3,$AD:$AD,$A18) -> 0 | G18: =SUMIFS($AE:$AE,$Z:$Z,G$3,$AD:$AD,$A18) -> 0 | H18: =SUMIFS($AE:$AE,$Z:$Z,H$3,$AD:$AD,$A18) -> 0 | I18: =SUMIFS($AE:$AE,$Z:$Z,I$3,$AD:$AD,$A18) -> 2640 | J18: =SUMIFS($AE:$AE,$Z:$Z,J$3,$AD:$AD,$A18) -> 2640 | K18: =SUMIFS($AE:$AE,$Z:$Z,K$3,$AD:$AD,$A18) -> 0 | ... O18: =SUMIFS($AE:$AE,$Z:$Z,O$3,$AD:$AD,$A18) -> 0 | P18: =SUM(D18:O18) -> 5280 | S18: 46295 | T18: 関東大会 | U18: 45961 | W18: 物販売上 | X18: 0 | Z18: 46295 | AA18: 関東大会 | AB18: 45930 | AD18: 会場費 | AE18: 795160
A19: 動画手数料（3.6%） | B19: =B18+1 -> 14 | C19: 支払手数料 | D19: =SUMIFS($AE:$AE,$Z:$Z,D$3,$AD:$AD,$A19) -> 0 | E19: =SUMIFS($AE:$AE,$Z:$Z,E$3,$AD:$AD,$A19) -> 0 | F19: =SUMIFS($AE:$AE,$Z:$Z,F$3,$AD:$AD,$A19) -> 0 | G19: =SUMIFS($AE:$AE,$Z:$Z,G$3,$AD:$AD,$A19) -> 0 | H19: =SUMIFS($AE:$AE,$Z:$Z,H$3,$AD:$AD,$A19) -> 0 | I19: =SUMIFS($AE:$AE,$Z:$Z,I$3,$AD:$AD,$A19) -> 7128 | J19: =SUMIFS($AE:$AE,$Z:$Z,J$3,$AD:$AD,$A19) -> 7128 | K19: =SUMIFS($AE:$AE,$Z:$Z,K$3,$AD:$AD,$A19) -> 0 | ... O19: =SUMIFS($AE:$AE,$Z:$Z,O$3,$AD:$AD,$A19) -> 0 | P19: =SUM(D19:O19) -> 14256 | S19: 46295 | T19: 関東大会 | U19: 45961 | W19: フォトレコ | X19: 0 | Z19: 46295 | AA19: 関東大会 | AB19: 45930 | AD19: 備品消耗品費 | AE19: 0
A20: アパレル仕入れ | B20: =B19+1 -> 15 | C20: 仕入高 | D20: =SUMIFS($AE:$AE,$Z:$Z,D$3,$AD:$AD,$A20) -> 0 | E20: =SUMIFS($AE:$AE,$Z:$Z,E$3,$AD:$AD,$A20) -> 0 | F20: =SUMIFS($AE:$AE,$Z:$Z,F$3,$AD:$AD,$A20) -> 0 | G20: =SUMIFS($AE:$AE,$Z:$Z,G$3,$AD:$AD,$A20) -> 0 | H20: =SUMIFS($AE:$AE,$Z:$Z,H$3,$AD:$AD,$A20) -> 0 | I20: =SUMIFS($AE:$AE,$Z:$Z,I$3,$AD:$AD,$A20) -> 1050000 | J20: =SUMIFS($AE:$AE,$Z:$Z,J$3,$AD:$AD,$A20) -> 1350000 | K20: =SUMIFS($AE:$AE,$Z:$Z,K$3,$AD:$AD,$A20) -> 0 | ... O20: =SUMIFS($AE:$AE,$Z:$Z,O$3,$AD:$AD,$A20) -> 0 | P20: =SUM(D20:O20) -> 2400000 | S20: 46295 | T20: 関東大会 | U20: 45961 | W20: 動画販売 | X20: 0 | Z20: 46295 | AA20: 関東大会 | AB20: 45930 | AD20: 運搬費 | AE20: 0
A21: 演出費 | B21: =B20+1 -> 16 | C21: SFF業務委託費 | D21: =SUMIFS($AE:$AE,$Z:$Z,D$3,$AD:$AD,$A21) -> 0 | E21: =SUMIFS($AE:$AE,$Z:$Z,E$3,$AD:$AD,$A21) -> 0 | F21: =SUMIFS($AE:$AE,$Z:$Z,F$3,$AD:$AD,$A21) -> 0 | G21: =SUMIFS($AE:$AE,$Z:$Z,G$3,$AD:$AD,$A21) -> 0 | H21: =SUMIFS($AE:$AE,$Z:$Z,H$3,$AD:$AD,$A21) -> 0 | I21: =SUMIFS($AE:$AE,$Z:$Z,I$3,$AD:$AD,$A21) -> 2500000 | J21: =SUMIFS($AE:$AE,$Z:$Z,J$3,$AD:$AD,$A21) -> 2500000 | K21: =SUMIFS($AE:$AE,$Z:$Z,K$3,$AD:$AD,$A21) -> 0 | ... O21: =SUMIFS($AE:$AE,$Z:$Z,O$3,$AD:$AD,$A21) -> 0 | P21: =SUM(D21:O21) -> 5000000 | S21: 46295 | T21: 関東大会 | U21: 45961 | W21: カラーリング | X21: 0 | Z21: 46295 | AA21: 関東大会 | AB21: 45930 | AD21: 旅費交通費 | AE21: 0
A22: 人件費（審査員） | B22: =B21+1 -> 17 | C22: SFF業務委託費 | D22: =SUMIFS($AE:$AE,$Z:$Z,D$3,$AD:$AD,$A22) -> 0 | E22: =SUMIFS($AE:$AE,$Z:$Z,E$3,$AD:$AD,$A22) -> 0 | F22: =SUMIFS($AE:$AE,$Z:$Z,F$3,$AD:$AD,$A22) -> 0 | G22: =SUMIFS($AE:$AE,$Z:$Z,G$3,$AD:$AD,$A22) -> 0 | H22: =SUMIFS($AE:$AE,$Z:$Z,H$3,$AD:$AD,$A22) -> 0 | I22: =SUMIFS($AE:$AE,$Z:$Z,I$3,$AD:$AD,$A22) -> 100000 | J22: =SUMIFS($AE:$AE,$Z:$Z,J$3,$AD:$AD,$A22) -> 100000 | K22: =SUMIFS($AE:$AE,$Z:$Z,K$3,$AD:$AD,$A22) -> 0 | ... O22: =SUMIFS($AE:$AE,$Z:$Z,O$3,$AD:$AD,$A22) -> 0 | P22: =SUM(D22:O22) -> 200000 | S22: 46295 | T22: 関東大会 | U22: 45961 | W22: SFFその他 | X22: 0 | Z22: 46295 | AA22: 関東大会 | AB22: 45930 | AD22: 打ち上げ代 | AE22: 0
A23: 人件費（MC） | B23: =B22+1 -> 18 | C23: SFF業務委託費 | D23: =SUMIFS($AE:$AE,$Z:$Z,D$3,$AD:$AD,$A23) -> 0 | E23: =SUMIFS($AE:$AE,$Z:$Z,E$3,$AD:$AD,$A23) -> 0 | F23: =SUMIFS($AE:$AE,$Z:$Z,F$3,$AD:$AD,$A23) -> 0 | G23: =SUMIFS($AE:$AE,$Z:$Z,G$3,$AD:$AD,$A23) -> 0 | H23: =SUMIFS($AE:$AE,$Z:$Z,H$3,$AD:$AD,$A23) -> 0 | I23: =SUMIFS($AE:$AE,$Z:$Z,I$3,$AD:$AD,$A23) -> 110000 | J23: =SUMIFS($AE:$AE,$Z:$Z,J$3,$AD:$AD,$A23) -> 110000 | K23: =SUMIFS($AE:$AE,$Z:$Z,K$3,$AD:$AD,$A23) -> 0 | ... O23: =SUMIFS($AE:$AE,$Z:$Z,O$3,$AD:$AD,$A23) -> 0 | P23: =SUM(D23:O23) -> 220000 | S23: 46295 | T23: 関東大会 | U23: 45991 | W23: 協賛売上 | X23: 0 | Z23: 46295 | AA23: 関東大会 | AB23: 45930 | AD23: 通信費 | AE23: 0
A24: 人件費（カメラ） | B24: =B23+1 -> 19 | C24: SFF業務委託費 | D24: =SUMIFS($AE:$AE,$Z:$Z,D$3,$AD:$AD,$A24) -> 0 | E24: =SUMIFS($AE:$AE,$Z:$Z,E$3,$AD:$AD,$A24) -> 0 | F24: =SUMIFS($AE:$AE,$Z:$Z,F$3,$AD:$AD,$A24) -> 0 | G24: =SUMIFS($AE:$AE,$Z:$Z,G$3,$AD:$AD,$A24) -> 0 | H24: =SUMIFS($AE:$AE,$Z:$Z,H$3,$AD:$AD,$A24) -> 0 | I24: =SUMIFS($AE:$AE,$Z:$Z,I$3,$AD:$AD,$A24) -> 700000 | J24: =SUMIFS($AE:$AE,$Z:$Z,J$3,$AD:$AD,$A24) -> 700000 | K24: =SUMIFS($AE:$AE,$Z:$Z,K$3,$AD:$AD,$A24) -> 0 | ... O24: =SUMIFS($AE:$AE,$Z:$Z,O$3,$AD:$AD,$A24) -> 0 | P24: =SUM(D24:O24) -> 1400000 | S24: 46295 | T24: 関東大会 | U24: 45991 | W24: 来場者売上 | X24: 0 | Z24: 46295 | AA24: 関東大会 | AB24: 45930 | AD24: スタッフTシャツ代 | AE24: 0
A25: その他外部委託費 | B25: =B24+1 -> 20 | C25: SFF業務委託費 | D25: =SUMIFS($AE:$AE,$Z:$Z,D$3,$AD:$AD,$A25) -> 0 | E25: =SUMIFS($AE:$AE,$Z:$Z,E$3,$AD:$AD,$A25) -> 0 | F25: =SUMIFS($AE:$AE,$Z:$Z,F$3,$AD:$AD,$A25) -> 0 | G25: =SUMIFS($AE:$AE,$Z:$Z,G$3,$AD:$AD,$A25) -> 0 | H25: =SUMIFS($AE:$AE,$Z:$Z,H$3,$AD:$AD,$A25) -> 0 | I25: =SUMIFS($AE:$AE,$Z:$Z,I$3,$AD:$AD,$A25) -> 2000000 | J25: =SUMIFS($AE:$AE,$Z:$Z,J$3,$AD:$AD,$A25) -> 7310000 | K25: =SUMIFS($AE:$AE,$Z:$Z,K$3,$AD:$AD,$A25) -> 0 | ... O25: =SUMIFS($AE:$AE,$Z:$Z,O$3,$AD:$AD,$A25) -> 0 | P25: =SUM(D25:O25) -> 9310000 | S25: 46295 | T25: 関東大会 | U25: 45991 | W25: 選手 | X25: 0 | Z25: 46295 | AA25: 関東大会 | AB25: 45930 | AD25: SFFその他 | AE25: 0
A26: 人件費（運営スタッフ） | B26: =B25+1 -> 21 | C26: SFF業務委託費 | D26: =SUMIFS($AE:$AE,$Z:$Z,D$3,$AD:$AD,$A26) -> 0 | E26: =SUMIFS($AE:$AE,$Z:$Z,E$3,$AD:$AD,$A26) -> 0 | F26: =SUMIFS($AE:$AE,$Z:$Z,F$3,$AD:$AD,$A26) -> 0 | G26: =SUMIFS($AE:$AE,$Z:$Z,G$3,$AD:$AD,$A26) -> 0 | H26: =SUMIFS($AE:$AE,$Z:$Z,H$3,$AD:$AD,$A26) -> 0 | I26: =SUMIFS($AE:$AE,$Z:$Z,I$3,$AD:$AD,$A26) -> 450000 | J26: =SUMIFS($AE:$AE,$Z:$Z,J$3,$AD:$AD,$A26) -> 450000 | K26: =SUMIFS($AE:$AE,$Z:$Z,K$3,$AD:$AD,$A26) -> 0 | ... O26: =SUMIFS($AE:$AE,$Z:$Z,O$3,$AD:$AD,$A26) -> 0 | P26: =SUM(D26:O26) -> 900000 | S26: 46295 | T26: 関東大会 | U26: 45991 | W26: バックサポート | X26: 0 | Z26: 46295 | AA26: 関東大会 | AB26: 45961 | AD26: 出場チケット手数料(3.6%) | AE26: 0
A27: メダルトロフィー代 | B27: =B26+1 -> 22 | C27: 備品・消耗品費 | D27: =SUMIFS($AE:$AE,$Z:$Z,D$3,$AD:$AD,$A27) -> 0 | E27: =SUMIFS($AE:$AE,$Z:$Z,E$3,$AD:$AD,$A27) -> 0 | F27: =SUMIFS($AE:$AE,$Z:$Z,F$3,$AD:$AD,$A27) -> 0 | G27: =SUMIFS($AE:$AE,$Z:$Z,G$3,$AD:$AD,$A27) -> 0 | H27: =SUMIFS($AE:$AE,$Z:$Z,H$3,$AD:$AD,$A27) -> 0 | I27: =SUMIFS($AE:$AE,$Z:$Z,I$3,$AD:$AD,$A27) -> 0 | J27: =SUMIFS($AE:$AE,$Z:$Z,J$3,$AD:$AD,$A27) -> 0 | K27: =SUMIFS($AE:$AE,$Z:$Z,K$3,$AD:$AD,$A27) -> 0 | ... O27: =SUMIFS($AE:$AE,$Z:$Z,O$3,$AD:$AD,$A27) -> 0 | P27: =SUM(D27:O27) -> 0 | S27: 46295 | T27: 関東大会 | U27: 45991 | W27: 物販売上 | X27: 0 | Z27: 46295 | AA27: 関東大会 | AB27: 45961 | AD27: 客席チケット手数料(3.6%) | AE27: 0
... A35: SFFその他 | B35: =B34+1 -> 30 | C35: --- | D35: =SUMIFS($AE:$AE,$Z:$Z,D$3,$AD:$AD,$A35) -> 0 | E35: =SUMIFS($AE:$AE,$Z:$Z,E$3,$AD:$AD,$A35) -> 0 | F35: =SUMIFS($AE:$AE,$Z:$Z,F$3,$AD:$AD,$A35) -> 0 | G35: =SUMIFS($AE:$AE,$Z:$Z,G$3,$AD:$AD,$A35) -> 0 | H35: =SUMIFS($AE:$AE,$Z:$Z,H$3,$AD:$AD,$A35) -> 0 | I35: =SUMIFS($AE:$AE,$Z:$Z,I$3,$AD:$AD,$A35) -> 765000 | J35: =SUMIFS($AE:$AE,$Z:$Z,J$3,$AD:$AD,$A35) -> 2105000 | K35: =SUMIFS($AE:$AE,$Z:$Z,K$3,$AD:$AD,$A35) -> 0 | ... O35: =SUMIFS($AE:$AE,$Z:$Z,O$3,$AD:$AD,$A35) -> 0 | P35: =SUM(D35:O35) -> 2870000 | S35: 46295 | T35: 関東大会 | U35: 46022 | W35: バックサポート | X35: 0 | Z35: 46295 | AA35: 関東大会 | AB35: 45961 | AD35: 人件費(カメラ) | AE35: 0
C36: 原価合計 | D36: =SUM(D15:D35) -> 0 | E36: =SUM(E15:E35) -> 0 | F36: =SUM(F15:F35) -> 0 | G36: =SUM(G15:G35) -> 0 | H36: =SUM(H15:H35) -> 0 | I36: =SUM(I15:I35) -> 12586100 | J36: =SUM(J15:J35) -> 21650160 | K36: =SUM(K15:K35) -> 0 | ... O36: =SUM(O15:O35) -> 0 | P36: =SUM(D36:O36) -> 34236260 | S36: 46295 | T36: 関東大会 | U36: 46022 | W36: 物販売上 | X36: 0 | Z36: 46295 | AA36: 関東大会 | AB36: 45961 | AD36: その他外部委託費 | AE36: 210000
C37: SFF粗利益 | D37: =D14-D36 -> 0 | E37: =E14-E36 -> 0 | F37: =F14-F36 -> 0 | G37: =G14-G36 -> 0 | H37: =H14-H36 -> 0 | I37: =I14-I36 -> 8056400 | J37: =J14-J36 -> 6092340 | K37: =K14-K36 -> 0 | ... O37: =O14-O36 -> 0 | P37: =SUM(D37:O37) -> 14148740 | S37: 46295 | T37: 関東大会 | U37: 46022 | W37: フォトレコ | X37: 0 | Z37: 46295 | AA37: 関東大会 | AB37: 45961 | AD37: 人件費(運営スタッフ) | AE37: 0
S38: 46295 | T38: 関東大会 | U38: 46022 | W38: 動画販売 | X38: 0 | Z38: 46295 | AA38: 関東大会 | AB38: 45961 | AD38: メダルトロフィー代 | AE38: 0
B39: Ⅲ.SFF販管費 | S39: 46295 | T39: 関東大会 | U39: 46022 | W39: カラーリング | X39: 0 | Z39: 46295 | AA39: 関東大会 | AB39: 45961 | AD39: 会場費 | AE39: 0
B40: =B35+1 -> 31 | C40: 通信費 | D40: 16900 | E40: 16900 | F40: 16900 | G40: 16900 | H40: 16900 | I40: 16900 | J40: 16900 | K40: 16900 | L40: 16900 | M40: 16900 | N40: 16900 | O40: 16900 | P40: =SUM(D40:O40) -> 202800 | Q40: Webサーバー費+データベース費 | S40: 46295 | T40: 関東大会 | U40: 46022 | W40: SFFその他 | X40: 0 | Z40: 46295 | AA40: 関東大会 | AB40: 45961 | AD40: 備品消耗品費 | AE40: 0
