Workbook

Sheet 工数サマリ (2)
A2: WBSのサマリ
C3: 時期 | D3: 清水 | E3: 平松 | F3: 菊池 | G3: 中尾 | H3: TBA | I3: 合計
B4: PJ管理 | C4: 5,６月 | D4: =SUMIF(#REF!,'工数サマリ (2)'!$B4,#REF!)/160 -> #REF! | E4: =SUMIF(#REF!,'工数サマリ (2)'!$B4,#REF!)/160 -> #REF! | F4: =SUMIF(#REF!,'工数サマリ (2)'!$B4,#REF!)/160 -> #REF! | G4: =SUMIF(#REF!,'工数サマリ (2)'!$B4,#REF!)/160 -> #REF! | H4: =SUMIF(#REF!,'工数サマリ (2)'!$B4,#REF!)/160 -> #REF! | I4: =SUM(D4:H4) -> #REF!
B5: 標準設計 | C5: 5,６月 | D5: =SUMIF(#REF!,'工数サマリ (2)'!$B5,#REF!)/160 -> #REF! | E5: =SUMIF(#REF!,'工数サマリ (2)'!$B5,#REF!)/160 -> #REF! | F5: =SUMIF(#REF!,'工数サマリ (2)'!$B5,#REF!)/160 -> #REF! | G5: =SUMIF(#REF!,'工数サマリ (2)'!$B5,#REF!)/160 -> #REF! | H5: =SUMIF(#REF!,'工数サマリ (2)'!$B5,#REF!)/160 -> #REF! | I5: =SUM(D5:H5) -> #REF!
B6: 合計 | D6: =SUM(D4:D5) -> #REF! | E6: =SUM(E4:E5) -> #REF! | F6: =SUM(F4:F5) -> #REF! | G6: =SUM(G4:G5) -> #REF! | H6: =SUM(H4:H5) -> #REF! | I6: =SUM(I4:I5) -> #REF!
E7: ↓
A8: 手動で数字を切りよく変更 | L8: 要員一覧
C9: 時期 | D9: 清水 | E9: 平松 | F9: 菊池 | G9: TBA(リーダークラス) | H9: TBA(メンバークラス) | I9: 合計 | J9: → | K9: メンバ | L9: 役割 | M9: 期間 | N9: 1月あたりの関与 | O9: 工数
B10: PJ管理 | C10: 8,8,10月 | D10: 0.5 | E10: 0.1 | F10: 0.2 | G10: 0.2 | H10: 0.3 | I10: =SUM(D10:H10) -> 1.3 | J10: → | K10: 清水 | L10: PM | M10: 3 | N10: 0.5 | O10: =N10*M10 -> 1.5
B11: 標準設計 | C11: 5,６月 | D11: 0.9 | E11: 0.1 | F11: 0.8 | G11: 0.4 | H11: 1.3 | I11: =SUM(D11:H11) -> 3.5 | J11: → | K11: 平松 | L11: PM補佐 | M11: 3 | N11: 0.1 | O11: =N11*M11 -> 0.3
B12: 合計 | D12: =SUM(D10:D11) -> 1.4 | E12: =SUM(E10:E11) -> 0.2 | F12: =SUM(F10:F11) -> 1 | G12: =SUM(G10:G11) -> 0.6 | H12: =SUM(H10:H11) -> 1.6 | I12: =SUM(I10:I11) -> 4.8 | J12: → | K12: 菊池 | L12: 設計・開発 | M12: 3 | N12: 0.5 | O12: =N12*M12 -> 1.5
B13: 1月あたり | C13: 2 | D13: =D12/$C$13 -> 0.7 | E13: =E12/$C$13 -> 0.1 | F13: =F12/$C$13 -> 0.5 | G13: =G12/$C$13 -> 0.3 | H13: =H12/$C$13 -> 0.8 | I13: =SUM(D13:H13) -> 2.4 | J13: → | K13: TBA(リーダークラス) | L13: PL | M13: 3 | N13: 0.5 | O13: =N13*M13 -> 1.5
K14: TBA(メンバークラス) | L14: 設計・開発 | M14: 3 | N14: 1 | O14: =N14*M14 -> 3
L15: 合計 | O15: =SUM(O10:O14) -> 7.8
K17: PrimeNavi登録時
K18: メンバ | L18: 役割 | M18: 期間 | N18: 1月あたりの関与
K19: 清水 | L19: PM | M19: 3 | N19: 0.7
K20: 平松 | L20: PM補佐 | M20: 3 | N20: 0.1
K21: 菊池 | L21: 設計・開発 | M21: 3 | N21: 0.6
K22: TBA(リーダークラス) | L22: PL | M22: 3 | N22: 0.7
K23: TBA(メンバークラス) | L23: 設計・開発 | M23: 3 | N23: 0.8
L24: 合計
N25: メンバ
N26: 清水
N27: 平松
N28: 菊池
N29: TBA(リーダークラス)
N30: TBA(メンバークラス)

Sheet WBS・見積もりフォーム
R1: 稼働工数
B2: フェーズ(Lv1) | D2: フェーズ(Lv2) | F2: 作業項目 | G2: 前提・条件 | I2: 1回あたりの人時工数 | J2: 回数 | K2: 合計人数 | L2: 伊藤 | M2: 岩瀬 | N2: 山口 勇 滋賀 泰樹 | O2: （SAP）TAB | P2: TAB | Q2: 工数合計 | R2: 伊藤 | S2: 岩瀬 | T2: 山口 勇 滋賀 泰樹 | U2: （SAP）TAB | V2: TAB
Q4: 契約工数 | R4: 0.5 | S4: 0.3 | T4: 0.5 | U4: 0.5 | V4: 1 | W4: =SUM(R4:V4) -> 2.8
Q5: 積上工数 | R5: =(SUM(R7:R71)+R6)/160 -> 1.2870313 | S5: =(SUM(S7:S71)+S6)/160 -> 0.76365625 | T5: =(SUM(T7:T71)+T6)/160 -> 1.0449062 | U5: =(SUM(U7:U71)+U6)/160 -> 1.2699063 | V5: =SUM(V7:V71)/160 -> 2.171875 | W5: =SUM(R5:V5) -> 6.537375
A6: 0 | B6: PJ管理 | C6: 0 | D6: 管理工数 | E6: 0 | F6: 進捗入力/課題起票/品質入力 | G6: 全体の10%（メンバの進捗管理：3%、顧客調整：3%、品質管理：4%） | Q6: =SUM(Q7:Q71)*0.1 -> 96.85 | R6: =Q6*0.5 -> 48.425 | S6: =Q6*0.1 -> 9.685 | T6: =Q6*0.1 -> 9.685 | U6: =Q6*0.1 -> 9.685 | V6: =Q6*0.2 -> 19.37
A7: 0 | B7: 定例会参加 | C7: 0 | D7: 打ち合わせ参加 | E7: 1 | F7: 週次定例会 | G7: 1.5h×週1回×15週×2人（1月中旬～3月末） | I7: 0.5 | J7: 11 | K7: =SUM(L7:P7) -> 5 | L7: 1 | M7: 1 | N7: 1 | O7: 1 | P7: 1 | Q7: =I7*J7*K7 -> 27.5 | R7: =IF(($I7*$J7*L7)=0,"",($I7*$J7*L7)) -> 5.5 | S7: =IF(($I7*$J7*M7)=0,"",($I7*$J7*M7)) -> 5.5 | T7: =IF(($I7*$J7*N7)=0,"",($I7*$J7*N7)) -> 5.5 | U7: =IF(($I7*$J7*O7)=0,"",($I7*$J7*O7)) -> 5.5 | V7: =IF(($I7*$J7*P7)=0,"",($I7*$J7*P7)) -> 5.5
A9: 2 | B9: システム要件定義 | C9: 2 | D9: 要件定義 | E9: 1 | F9: Poc結果状況の確認 | G9: 1h×全2回×5人（インフォマティカよりレクチャー） | I9: 1 | J9: 2 | K9: =SUM(L9:P9) -> 5 | L9: 1 | M9: 1 | N9: 1 | O9: 1 | P9: 1 | Q9: =I9*J9*K9 -> 10 | R9: =IF(($I9*$J9*L9)=0,"",($I9*$J9*L9)) -> 2 | S9: =IF(($I9*$J9*M9)=0,"",($I9*$J9*M9)) -> 2 | T9: =IF(($I9*$J9*N9)=0,"",($I9*$J9*N9)) -> 2 | U9: =IF(($I9*$J9*O9)=0,"",($I9*$J9*O9)) -> 2 | V9: =IF(($I9*$J9*P9)=0,"",($I9*$J9*P9)) -> 2
A10: 1 | B10: 業務要件定義 | C10: 1 | D10: 要件定義 | E10: 2 | F10: データ戦略確認会 | G10: 1h×全2回×５人(データ総研よりレクチャー） | I10: 1 | J10: 2 | K10: =SUM(L10:P10) -> 5 | L10: 1 | M10: 1 | N10: 1 | O10: 1 | P10: 1 | Q10: =I10*J10*K10 -> 10 | R10: =IF(($I10*$J10*L10)=0,"",($I10*$J10*L10)) -> 2 | S10: =IF(($I10*$J10*M10)=0,"",($I10*$J10*M10)) -> 2 | T10: =IF(($I10*$J10*N10)=0,"",($I10*$J10*N10)) -> 2 | U10: =IF(($I10*$J10*O10)=0,"",($I10*$J10*O10)) -> 2 | V10: =IF(($I10*$J10*P10)=0,"",($I10*$J10*P10)) -> 2
A11: 1 | B11: 業務要件定義 | C11: 1 | D11: 要件定義 | E11: 3 | F11: 要件整理・方針検討 | G11: 10h×全１回×2人 | I11: 10 | J11: 1 | K11: =SUM(L11:P11) -> 3 | L11: 0.5 | M11: 0.5 | N11: 0.5 | O11: 0.5 | P11: 1 | Q11: =I11*J11*K11 -> 30 | R11: =IF(($I11*$J11*L11)=0,"",($I11*$J11*L11)) -> 5 | S11: =IF(($I11*$J11*M11)=0,"",($I11*$J11*M11)) -> 5 | T11: =IF(($I11*$J11*N11)=0,"",($I11*$J11*N11)) -> 5 | U11: =IF(($I11*$J11*O11)=0,"",($I11*$J11*O11)) -> 5 | V11: =IF(($I11*$J11*P11)=0,"",($I11*$J11*P11)) -> 10
A12: 1 | B12: 業務要件定義 | C12: 1 | D12: 要件定義 | E12: 4 | F12: 要件定義書作成 | G12: 1h×10ページ×全2回×1人 | I12: 10 | J12: 2 | K12: =SUM(L12:P12) -> 2 | L12: 0.5 | O12: 0.5 | P12: 1 | Q12: =I12*J12*K12 -> 40 | R12: =IF(($I12*$J12*L12)=0,"",($I12*$J12*L12)) -> 10 | S12: =IF(($I12*$J12*M12)=0,"",($I12*$J12*M12)) | T12: =IF(($I12*$J12*N12)=0,"",($I12*$J12*N12)) | U12: =IF(($I12*$J12*O12)=0,"",($I12*$J12*O12)) -> 10 | V12: =IF(($I12*$J12*P12)=0,"",($I12*$J12*P12)) -> 20
A13: 1 | B13: 業務要件定義 | C13: 1 | D13: 要件定義 | E13: 5 | F13: 要件定義書内部レビュー | G13: 1h×全2回×2人 | I13: 1 | J13: 2 | K13: =SUM(L13:P13) -> 5 | L13: 1 | M13: 1 | N13: 1 | O13: 1 | P13: 1 | Q13: =I13*J13*K13 -> 10 | R13: =IF(($I13*$J13*L13)=0,"",($I13*$J13*L13)) -> 2 | S13: =IF(($I13*$J13*M13)=0,"",($I13*$J13*M13)) -> 2 | T13: =IF(($I13*$J13*N13)=0,"",($I13*$J13*N13)) -> 2 | U13: =IF(($I13*$J13*O13)=0,"",($I13*$J13*O13)) -> 2 | V13: =IF(($I13*$J13*P13)=0,"",($I13*$J13*P13)) -> 2
A14: 1 | B14: 業務要件定義 | C14: 1 | D14: 要件定義 | E14: 6 | F14: 要件定義書内部レビュー後修正 | G14: 1h×全2回×1人 | I14: 1 | J14: 2 | K14: =SUM(L14:P14) -> 2 | O14: 1 | P14: 1 | Q14: =I14*J14*K14 -> 4 | R14: =IF(($I14*$J14*L14)=0,"",($I14*$J14*L14)) | S14: =IF(($I14*$J14*M14)=0,"",($I14*$J14*M14)) | T14: =IF(($I14*$J14*N14)=0,"",($I14*$J14*N14)) | U14: =IF(($I14*$J14*O14)=0,"",($I14*$J14*O14)) -> 2 | V14: =IF(($I14*$J14*P14)=0,"",($I14*$J14*P14)) -> 2
A15: 1 | B15: 業務要件定義 | C15: 1 | D15: 要件定義 | E15: 7 | F15: 要件定義書顧客レビュー | G15: 1h×全2回×1人 | I15: 1 | J15: 2 | K15: =SUM(L15:P15) -> 5 | L15: 1 | M15: 1 | N15: 1 | O15: 1 | P15: 1 | Q15: =I15*J15*K15 -> 10 | R15: =IF(($I15*$J15*L15)=0,"",($I15*$J15*L15)) -> 2 | S15: =IF(($I15*$J15*M15)=0,"",($I15*$J15*M15)) -> 2 | T15: =IF(($I15*$J15*N15)=0,"",($I15*$J15*N15)) -> 2 | U15: =IF(($I15*$J15*O15)=0,"",($I15*$J15*O15)) -> 2 | V15: =IF(($I15*$J15*P15)=0,"",($I15*$J15*P15)) -> 2
A16: 1 | B16: 業務要件定義 | C16: 1 | D16: 要件定義 | E16: 8 | F16: 要件定義書顧客レビュー後修正 | G16: 1h×全2回×1人 | I16: 1 | J16: 2 | K16: =SUM(L16:P16) -> 1 | P16: 1 | Q16: =I16*J16*K16 -> 2 | R16: =IF(($I16*$J16*L16)=0,"",($I16*$J16*L16)) | S16: =IF(($I16*$J16*M16)=0,"",($I16*$J16*M16)) | T16: =IF(($I16*$J16*N16)=0,"",($I16*$J16*N16)) | U16: =IF(($I16*$J16*O16)=0,"",($I16*$J16*O16)) | V16: =IF(($I16*$J16*P16)=0,"",($I16*$J16*P16)) -> 2
R17: =IF(($I17*$J17*L17)=0,"",($I17*$J17*L17)) | S17: =IF(($I17*$J17*M17)=0,"",($I17*$J17*M17)) | T17: =IF(($I17*$J17*N17)=0,"",($I17*$J17*N17)) | U17: =IF(($I17*$J17*O17)=0,"",($I17*$J17*O17)) | V17: =IF(($I17*$J17*P17)=0,"",($I17*$J17*P17))
A18: 2 | B18: システム要件定義 | C18: 2 | D18: データモデリング | E18: 1 | F18: 概念データモデリング確認 | G18: 1h×全2回×2人 | I18: 1 | J18: 2 | K18: =SUM(L18:P18) -> 3 | L18: 0.5 | M18: 0.5 | N18: 0.5 | O18: 0.5 | P18: 1 | Q18: =I18*J18*K18 -> 6 | R18: =IF(($I18*$J18*L18)=0,"",($I18*$J18*L18)) -> 1 | S18: =IF(($I18*$J18*M18)=0,"",($I18*$J18*M18)) -> 1 | T18: =IF(($I18*$J18*N18)=0,"",($I18*$J18*N18)) -> 1 | U18: =IF(($I18*$J18*O18)=0,"",($I18*$J18*O18)) -> 1 | V18: =IF(($I18*$J18*P18)=0,"",($I18*$J18*P18)) -> 2
A19: 2 | B19: システム要件定義 | C19: 2 | D19: データモデリング | E19: 2 | F19: 要件トレーサビリティ整理 | G19: 1h×全2回×2人 | I19: 1 | J19: 2 | K19: =SUM(L19:P19) -> 3 | L19: 0.5 | M19: 0.5 | N19: 0.5 | O19: 0.5 | P19: 1 | Q19: =I19*J19*K19 -> 6 | R19: =IF(($I19*$J19*L19)=0,"",($I19*$J19*L19)) -> 1 | S19: =IF(($I19*$J19*M19)=0,"",($I19*$J19*M19)) -> 1 | T19: =IF(($I19*$J19*N19)=0,"",($I19*$J19*N19)) -> 1 | U19: =IF(($I19*$J19*O19)=0,"",($I19*$J19*O19)) -> 1 | V19: =IF(($I19*$J19*P19)=0,"",($I19*$J19*P19)) -> 2
A20: 2 | B20: システム要件定義 | C20: 2 | D20: データモデリング | E20: 3 | F20: 要件トレーサビリティ定義書作成 | G20: 1h×10ページ×全2回×1人 | I20: 10 | J20: 2 | K20: =SUM(L20:P20) -> 2 | L20: 0.5 | O20: 0.5 | P20: 1 | Q20: =I20*J20*K20 -> 40 | R20: =IF(($I20*$J20*L20)=0,"",($I20*$J20*L20)) -> 10 | S20: =IF(($I20*$J20*M20)=0,"",($I20*$J20*M20)) | T20: =IF(($I20*$J20*N20)=0,"",($I20*$J20*N20)) | U20: =IF(($I20*$J20*O20)=0,"",($I20*$J20*O20)) -> 10 | V20: =IF(($I20*$J20*P20)=0,"",($I20*$J20*P20)) -> 20
A21: ４ | B21: システム要件定義 | C21: 3 | D21: データモデリング | E21: 4 | F21: 要件トレーサビリティ定義書内部レビュー | G21: 1h×全1回×４人 | I21: 1 | J21: 1 | K21: =SUM(L21:P21) -> 5 | L21: 1 | M21: 1 | N21: 1 | O21: 1 | P21: 1 | Q21: =I21*J21*K21 -> 5 | R21: =IF(($I21*$J21*L21)=0,"",($I21*$J21*L21)) -> 1 | S21: =IF(($I21*$J21*M21)=0,"",($I21*$J21*M21)) -> 1 | T21: =IF(($I21*$J21*N21)=0,"",($I21*$J21*N21)) -> 1 | U21: =IF(($I21*$J21*O21)=0,"",($I21*$J21*O21)) -> 1 | V21: =IF(($I21*$J21*P21)=0,"",($I21*$J21*P21)) -> 1
A22: 2 | B22: システム要件定義 | C22: 2 | D22: データモデリング | E22: 5 | F22: 要件トレーサビリティ定義書内部レビュー後修正 | G22: 1h×全2回×1人 | I22: 1 | J22: 2 | K22: =SUM(L22:P22) -> 2 | O22: 1 | P22: 1 | Q22: =I22*J22*K22 -> 4 | R22: =IF(($I22*$J22*L22)=0,"",($I22*$J22*L22)) | S22: =IF(($I22*$J22*M22)=0,"",($I22*$J22*M22)) | T22: =IF(($I22*$J22*N22)=0,"",($I22*$J22*N22)) | U22: =IF(($I22*$J22*O22)=0,"",($I22*$J22*O22)) -> 2 | V22: =IF(($I22*$J22*P22)=0,"",($I22*$J22*P22)) -> 2
A23: 2 | B23: システム要件定義 | C23: 2 | D23: データモデリング | E23: 6 | F23: 要件トレーサビリティ定義書顧客レビュー | G23: 1h×全1回×５人 | I23: 1 | J23: 1 | K23: =SUM(L23:P23) -> 5 | L23: 1 | M23: 1 | N23: 1 | O23: 1 | P23: 1 | Q23: =I23*J23*K23 -> 5 | R23: =IF(($I23*$J23*L23)=0,"",($I23*$J23*L23)) -> 1 | S23: =IF(($I23*$J23*M23)=0,"",($I23*$J23*M23)) -> 1 | T23: =IF(($I23*$J23*N23)=0,"",($I23*$J23*N23)) -> 1 | U23: =IF(($I23*$J23*O23)=0,"",($I23*$J23*O23)) -> 1 | V23: =IF(($I23*$J23*P23)=0,"",($I23*$J23*P23)) -> 1
A24: 2 | B24: システム要件定義 | C24: 2 | D24: データモデリング | E24: 7 | F24: 要件トレーサビリティ定義書顧客レビュー後修正 | G24: 1h×全2回×1人 | I24: 1 | J24: 2 | K24: =SUM(L24:P24) -> 2 | O24: 1 | P24: 1 | Q24: =I24*J24*K24 -> 4 | R24: =IF(($I24*$J24*L24)=0,"",($I24*$J24*L24)) | S24: =IF(($I24*$J24*M24)=0,"",($I24*$J24*M24)) | T24: =IF(($I24*$J24*N24)=0,"",($I24*$J24*N24)) | U24: =IF(($I24*$J24*O24)=0,"",($I24*$J24*O24)) -> 2 | V24: =IF(($I24*$J24*P24)=0,"",($I24*$J24*P24)) -> 2
R25: =IF(($I25*$J25*L25)=0,"",($I25*$J25*L25)) | S25: =IF(($I25*$J25*M25)=0,"",($I25*$J25*M25)) | T25: =IF(($I25*$J25*N25)=0,"",($I25*$J25*N25)) | U25: =IF(($I25*$J25*O25)=0,"",($I25*$J25*O25)) | V25: =IF(($I25*$J25*P25)=0,"",($I25*$J25*P25))
A26: ３ | B26: 現状データ分析 | C26: ３ | D26: 開発支援 | E26: 1 | F26: 現状分析（対象システム・テーブル調査） | G26: 10h×全1回×2人 | I26: 10 | J26: 1 | K26: =SUM(L26:P26) -> 3 | L26: 0.5 | M26: 0.5 | N26: 0.5 | O26: 0.5 | P26: 1 | Q26: =I26*J26*K26 -> 30 | R26: =IF(($I26*$J26*L26)=0,"",($I26*$J26*L26)) -> 5 | S26: =IF(($I26*$J26*M26)=0,"",($I26*$J26*M26)) -> 5 | T26: =IF(($I26*$J26*N26)=0,"",($I26*$J26*N26)) -> 5 | U26: =IF(($I26*$J26*O26)=0,"",($I26*$J26*O26)) -> 5 | V26: =IF(($I26*$J26*P26)=0,"",($I26*$J26*P26)) -> 10
A27: ３ | B27: 現状データ分析 | C27: ３ | D27: 開発支援 | E27: 2 | F27: データ品質プロファイリング | G27: 10h×全1回×2人 | I27: 10 | J27: 1 | K27: =SUM(L27:P27) -> 3 | L27: 0.5 | M27: 0.5 | N27: 0.5 | O27: 0.5 | P27: 1 | Q27: =I27*J27*K27 -> 30 | R27: =IF(($I27*$J27*L27)=0,"",($I27*$J27*L27)) -> 5 | S27: =IF(($I27*$J27*M27)=0,"",($I27*$J27*M27)) -> 5 | T27: =IF(($I27*$J27*N27)=0,"",($I27*$J27*N27)) -> 5 | U27: =IF(($I27*$J27*O27)=0,"",($I27*$J27*O27)) -> 5 | V27: =IF(($I27*$J27*P27)=0,"",($I27*$J27*P27)) -> 10
A28: ３ | B28: 現状データ分析 | C28: ３ | D28: 開発支援 | E28: 3 | F28: 課題整理 | G28: 10h×全1回×2人 | I28: 10 | J28: 1 | K28: =SUM(L28:P28) -> 3 | L28: 0.5 | M28: 0.5 | N28: 0.5 | O28: 0.5 | P28: 1 | Q28: =I28*J28*K28 -> 30 | R28: =IF(($I28*$J28*L28)=0,"",($I28*$J28*L28)) -> 5 | S28: =IF(($I28*$J28*M28)=0,"",($I28*$J28*M28)) -> 5 | T28: =IF(($I28*$J28*N28)=0,"",($I28*$J28*N28)) -> 5 | U28: =IF(($I28*$J28*O28)=0,"",($I28*$J28*O28)) -> 5 | V28: =IF(($I28*$J28*P28)=0,"",($I28*$J28*P28)) -> 10
A29: ３ | B29: 現状データ分析 | C29: ３ | D29: 開発支援 | E29: 4 | F29: データ整備方針書作成 | G29: 1h×10ページ×全2回×1人 | I29: 10 | J29: 2 | K29: =SUM(L29:P29) -> 2 | L29: 0.5 | O29: 0.5 | P29: 1 | Q29: =I29*J29*K29 -> 40 | R29: =IF(($I29*$J29*L29)=0,"",($I29*$J29*L29)) -> 10 | S29: =IF(($I29*$J29*M29)=0,"",($I29*$J29*M29)) | T29: =IF(($I29*$J29*N29)=0,"",($I29*$J29*N29)) | U29: =IF(($I29*$J29*O29)=0,"",($I29*$J29*O29)) -> 10 | V29: =IF(($I29*$J29*P29)=0,"",($I29*$J29*P29)) -> 20
A30: ３ | B30: 現状データ分析 | C30: ３ | D30: 開発支援 | E30: 2 | F30: データ整備方針書内部レビュー | G30: 1h×全1回×４人 | I30: 1 | J30: 1 | K30: =SUM(L30:P30) -> 5 | L30: 1 | M30: 1 | N30: 1 | O30: 1 | P30: 1 | Q30: =I30*J30*K30 -> 5 | R30: =IF(($I30*$J30*L30)=0,"",($I30*$J30*L30)) -> 1 | S30: =IF(($I30*$J30*M30)=0,"",($I30*$J30*M30)) -> 1 | T30: =IF(($I30*$J30*N30)=0,"",($I30*$J30*N30)) -> 1 | U30: =IF(($I30*$J30*O30)=0,"",($I30*$J30*O30)) -> 1 | V30: =IF(($I30*$J30*P30)=0,"",($I30*$J30*P30)) -> 1
A31: ３ | B31: 現状データ分析 | C31: ３ | D31: 開発支援 | E31: 3 | F31: データ整備方針書内部レビュー後修正 | G31: 1h×全2回×1人 | I31: 1 | J31: 2 | K31: =SUM(L31:P31) -> 2 | O31: 1 | P31: 1 | Q31: =I31*J31*K31 -> 4 | R31: =IF(($I31*$J31*L31)=0,"",($I31*$J31*L31)) | S31: =IF(($I31*$J31*M31)=0,"",($I31*$J31*M31)) | T31: =IF(($I31*$J31*N31)=0,"",($I31*$J31*N31)) | U31: =IF(($I31*$J31*O31)=0,"",($I31*$J31*O31)) -> 2 | V31: =IF(($I31*$J31*P31)=0,"",($I31*$J31*P31)) -> 2
A32: ３ | B32: 現状データ分析 | C32: ３ | D32: 開発支援 | E32: 4 | F32: データ整備方針書顧客レビュー | G32: 1h×全1回×５人 | I32: 1 | J32: 1 | K32: =SUM(L32:P32) -> 5 | L32: 1 | M32: 1 | N32: 1 | O32: 1 | P32: 1 | Q32: =I32*J32*K32 -> 5 | R32: =IF(($I32*$J32*L32)=0,"",($I32*$J32*L32)) -> 1 | S32: =IF(($I32*$J32*M32)=0,"",($I32*$J32*M32)) -> 1 | T32: =IF(($I32*$J32*N32)=0,"",($I32*$J32*N32)) -> 1 | U32: =IF(($I32*$J32*O32)=0,"",($I32*$J32*O32)) -> 1 | V32: =IF(($I32*$J32*P32)=0,"",($I32*$J32*P32)) -> 1
A33: ３ | B33: 現状データ分析 | C33: ３ | D33: 開発支援 | E33: 5 | F33: データ整備方針書顧客レビュー後修正 | G33: 1h×全2回×1人 | I33: 1 | J33: 2 | K33: =SUM(L33:P33) -> 2 | O33: 1 | P33: 1 | Q33: =I33*J33*K33 -> 4 | R33: =IF(($I33*$J33*L33)=0,"",($I33*$J33*L33)) | S33: =IF(($I33*$J33*M33)=0,"",($I33*$J33*M33)) | T33: =IF(($I33*$J33*N33)=0,"",($I33*$J33*N33)) | U33: =IF(($I33*$J33*O33)=0,"",($I33*$J33*O33)) -> 2 | V33: =IF(($I33*$J33*P33)=0,"",($I33*$J33*P33)) -> 2
R34: =IF(($I34*$J34*L34)=0,"",($I34*$J34*L34)) | S34: =IF(($I34*$J34*M34)=0,"",($I34*$J34*M34)) | T34: =IF(($I34*$J34*N34)=0,"",($I34*$J34*N34)) | U34: =IF(($I34*$J34*O34)=0,"",($I34*$J34*O34)) | V34: =IF(($I34*$J34*P34)=0,"",($I34*$J34*P34))
A35: ４ | B35: 設計 | C35: ４ | D35: 分析・業務設計 | E35: 1 | F35: MDM論理・物理設計 | G35: 10h×全１回×2人 | I35: 10 | J35: 1 | K35: =SUM(L35:P35) -> 3 | L35: 0.5 | M35: 0.5 | N35: 0.5 | O35: 0.5 | P35: 1 | Q35: =I35*J35*K35 -> 30 | R35: =IF(($I35*$J35*L35)=0,"",($I35*$J35*L35)) -> 5 | S35: =IF(($I35*$J35*M35)=0,"",($I35*$J35*M35)) -> 5 | T35: =IF(($I35*$J35*N35)=0,"",($I35*$J35*N35)) -> 5 | U35: =IF(($I35*$J35*O35)=0,"",($I35*$J35*O35)) -> 5 | V35: =IF(($I35*$J35*P35)=0,"",($I35*$J35*P35)) -> 10
A36: ４ | B36: 設計 | C36: ４ | D36: 分析・業務設計 | E36: 2 | F36: 画面・連携設計 | G36: 10h×全１回×2人 | I36: 10 | J36: 1 | K36: =SUM(L36:P36) -> 3 | L36: 0.5 | M36: 0.5 | N36: 0.5 | O36: 0.5 | P36: 1 | Q36: =I36*J36*K36 -> 30 | R36: =IF(($I36*$J36*L36)=0,"",($I36*$J36*L36)) -> 5 | S36: =IF(($I36*$J36*M36)=0,"",($I36*$J36*M36)) -> 5 | T36: =IF(($I36*$J36*N36)=0,"",($I36*$J36*N36)) -> 5 | U36: =IF(($I36*$J36*O36)=0,"",($I36*$J36*O36)) -> 5 | V36: =IF(($I36*$J36*P36)=0,"",($I36*$J36*P36)) -> 10
A37: ４ | B37: 設計 | C37: ４ | D37: 分析・業務設計 | E37: 3 | F37: 設計書作成 | G37: 1h×10ページ×全1回×2人 | I37: 10 | J37: 1 | K37: =SUM(L37:P37) -> 3 | L37: 0.5 | N37: 1 | O37: 0.5 | P37: 1 | Q37: =I37*J37*K37 -> 30 | R37: =IF(($I37*$J37*L37)=0,"",($I37*$J37*L37)) -> 5 | S37: =IF(($I37*$J37*M37)=0,"",($I37*$J37*M37)) | T37: =IF(($I37*$J37*N37)=0,"",($I37*$J37*N37)) -> 10 | U37: =IF(($I37*$J37*O37)=0,"",($I37*$J37*O37)) -> 5 | V37: =IF(($I37*$J37*P37)=0,"",($I37*$J37*P37)) -> 10
A38: ４ | B38: 設計 | C38: ４ | D38: 分析・業務設計 | E38: 4 | F38: 設計書内部レビュー | G38: 1h×全1回×４人 | I38: 1 | J38: 1 | K38: =SUM(L38:P38) -> 5 | L38: 1 | M38: 1 | N38: 1 | O38: 1 | P38: 1 | Q38: =I38*J38*K38 -> 5 | R38: =IF(($I38*$J38*L38)=0,"",($I38*$J38*L38)) -> 1 | S38: =IF(($I38*$J38*M38)=0,"",($I38*$J38*M38)) -> 1 | T38: =IF(($I38*$J38*N38)=0,"",($I38*$J38*N38)) -> 1 | U38: =IF(($I38*$J38*O38)=0,"",($I38*$J38*O38)) -> 1 | V38: =IF(($I38*$J38*P38)=0,"",($I38*$J38*P38)) -> 1
A39: ４ | B39: 設計 | C39: ４ | D39: 分析・業務設計 | E39: 5 | F39: 設計書内部レビュー後修正 | G39: 1h×全2回×1人 | I39: 1 | J39: 2 | K39: =SUM(L39:P39) -> 2 | O39: 1 | P39: 1 | Q39: =I39*J39*K39 -> 4 | R39: =IF(($I39*$J39*L39)=0,"",($I39*$J39*L39)) | S39: =IF(($I39*$J39*M39)=0,"",($I39*$J39*M39)) | T39: =IF(($I39*$J39*N39)=0,"",($I39*$J39*N39)) | U39: =IF(($I39*$J39*O39)=0,"",($I39*$J39*O39)) -> 2 | V39: =IF(($I39*$J39*P39)=0,"",($I39*$J39*P39)) -> 2
A40: ４ | B40: 設計 | C40: ４ | D40: 分析・業務設計 | E40: 6 | F40: 設計書顧客レビュー | G40: 1h×全1回×４人 | I40: 1 | J40: 1 | K40: =SUM(L40:P40) -> 5 | L40: 1 | M40: 1 | N40: 1 | O40: 1 | P40: 1 | Q40: =I40*J40*K40 -> 5 | R40: =IF(($I40*$J40*L40)=0,"",($I40*$J40*L40)) -> 1 | S40: =IF(($I40*$J40*M40)=0,"",($I40*$J40*M40)) -> 1 | T40: =IF(($I40*$J40*N40)=0,"",($I40*$J40*N40)) -> 1 | U40: =IF(($I40*$J40*O40)=0,"",($I40*$J40*O40)) -> 1 | V40: =IF(($I40*$J40*P40)=0,"",($I40*$J40*P40)) -> 1
A41: ４ | B41: 設計 | C41: ４ | D41: 分析・業務設計 | E41: 7 | F41: 設計書顧客レビュー後修正 | G41: 1h×全2回×1人 | I41: 1 | J41: 2 | K41: =SUM(L41:P41) -> 2 | O41: 1 | P41: 1 | Q41: =I41*J41*K41 -> 4 | R41: =IF(($I41*$J41*L41)=0,"",($I41*$J41*L41)) | S41: =IF(($I41*$J41*M41)=0,"",($I41*$J41*M41)) | T41: =IF(($I41*$J41*N41)=0,"",($I41*$J41*N41)) | U41: =IF(($I41*$J41*O41)=0,"",($I41*$J41*O41)) -> 2 | V41: =IF(($I41*$J41*P41)=0,"",($I41*$J41*P41)) -> 2
R42: =IF(($I42*$J42*L42)=0,"",($I42*$J42*L42)) | S42: =IF(($I42*$J42*M42)=0,"",($I42*$J42*M42)) | T42: =IF(($I42*$J42*N42)=0,"",($I42*$J42*N42)) | U42: =IF(($I42*$J42*O42)=0,"",($I42*$J42*O42)) | V42: =IF(($I42*$J42*P42)=0,"",($I42*$J42*P42))
...
